Workbook

Sheet 依賽道-個人紀錄
A1: 作者：Jintei Sacc系統 | I1: 作者：FoxBG CVS系統(RIP) | Q1: 作者：StarRiver Arts 跨系統 | Y1: @dropdown
A2: Akina Downhill秋名/下行 | E2: Akina Uphill秋名/上行 | I2: Nagao Downhill 長尾/下行 | M2: Shomaru Clockwise 正丸/順行 | Q2: 9Turns CVS Downhill 九彎十八拐/下行 | U2: 9Turns CVS Uphill 九彎十八拐/上行
A3: =IFERROR(__xludf.DUMMYFUNCTION("LET( 賽道, ""Akina"", 路線, ""DH"", 系統, ""Sacc"", 原始, FILTER('歷史紀錄'!$E$2:$H1168, '歷史紀錄'!$B$2:$B1168=賽道, '歷史紀錄'!$C$2:$C1168=路線, '歷史紀錄'!$I$2:$I1168=系統), 排序後, SORT(原始, 2, TRUE), 玩家, INDEX(排序後,,1), 唯一玩家, UNIQUE(玩家), 結果, MAP(唯一玩家, LAMBDA(p, "&" INDEX(FILTER(排序後, INDEX(排序後,,1)=p),1,0) )), 表頭, {""Player玩家"",""Time時間"",""Car車種"",""Platform平台""}, VSTACK(表頭, 結果) ) "),"Player玩家") -> Player玩家 | B3: =IFERROR(__xludf.DUMMYFUNCTION("""COMPUTED_VALUE"""),"Time時間") -> Time時間 | C3: =IFERROR(__xludf.DUMMYFUNCTION("""COMPUTED_VALUE"""),"Car車種") -> Car車種 | D3: =IFERROR(__xludf.DUMMYFUNCTION("""COMPUTED_VALUE"""),"Platform平台") -> Platform平台 | E3: =IFERROR(__xludf.DUMMYFUNCTION("LET( 賽道, ""Akina"", 路線, ""UH"", 系統, ""Sacc"", 原始, FILTER('歷史紀錄'!E2:H1168, '歷史紀錄'!B2:B1168=賽道, '歷史紀錄'!C2:C1168=路線, '歷史紀錄'!I2:I1168=系統), 排序後, SORT(原始, 2, TRUE), 玩家, INDEX(排序後,,1), 唯一玩家, UNIQUE(玩家), 結果, MAP(唯一玩家, LAMBDA(p, INDEX(FIL"&"TER(排序後, INDEX(排序後,,1)=p),1,0) )), 表頭, {""Player玩家"",""Time時間"",""Car車種"",""Platform平台""}, VSTACK(表頭, 結果) ) "),"Player玩家") -> Player玩家 | F3: =IFERROR(__xludf.DUMMYFUNCTION("""COMPUTED_VALUE"""),"Time時間") -> Time時間 | G3: =IFERROR(__xludf.DUMMYFUNCTION("""COMPUTED_VALUE"""),"Car車種") -> Car車種 | H3: =IFERROR(__xludf.DUMMYFUNCTION("""COMPUTED_VALUE"""),"Platform平台") -> Platform平台 | I3: =IFERROR(__xludf.DUMMYFUNCTION("LET( 賽道, ""Nagao"", 路線, ""DH"", 系統, ""CVS"", 原始, FILTER('歷史紀錄'!E2:H1168, '歷史紀錄'!B2:B1168=賽道, '歷史紀錄'!C2:C1168=路線, '歷史紀錄'!I2:I1168=系統), 排序後, SORT(原始, 2, TRUE), 玩家, INDEX(排序後,,1), 唯一玩家, UNIQUE(玩家), 結果, MAP(唯一玩家, LAMBDA(p, INDEX(FILT"&"ER(排序後, INDEX(排序後,,1)=p),1,0) )), 表頭, {""Player玩家"",""Time時間"",""Car車種"",""Platform平台""}, VSTACK(表頭, 結果) ) "),"Player玩家") -> Player玩家 | J3: =IFERROR(__xludf.DUMMYFUNCTION("""COMPUTED_VALUE"""),"Time時間") -> Time時間 | K3: =IFERROR(__xludf.DUMMYFUNCTION("""COMPUTED_VALUE"""),"Car車種") -> Car車種 | L3: =IFERROR(__xludf.DUMMYFUNCTION("""COMPUTED_VALUE"""),"Platform平台") -> Platform平台 | M3: =IFERROR(__xludf.DUMMYFUNCTION("LET( 賽道, ""Shomaru"", 路線, """", 系統, ""CVS"", 原始, FILTER('歷史紀錄'!E2:H1168, '歷史紀錄'!B2:B1168=賽道, '歷史紀錄'!C2:C1168=路線, '歷史紀錄'!I2:I1168=系統), 排序後, SORT(原始, 2, TRUE), 玩家, INDEX(排序後,,1), 唯一玩家, UNIQUE(玩家), 結果, MAP(唯一玩家, LAMBDA(p, INDEX(FILT"&"ER(排序後, INDEX(排序後,,1)=p),1,0) )), 表頭, {""Player玩家"",""Time時間"",""Car車種"",""Platform平台""}, VSTACK(表頭, 結果) ) "),"Player玩家") -> Player玩家 | N3: =IFERROR(__xludf.DUMMYFUNCTION("""COMPUTED_VALUE"""),"Time時間") -> Time時間 | O3: =IFERROR(__xludf.DUMMYFUNCTION("""COMPUTED_VALUE"""),"Car車種") -> Car車種 | P3: =IFERROR(__xludf.DUMMYFUNCTION("""COMPUTED_VALUE"""),"Platform平台") -> Platform平台 | Q3: =IFERROR(__xludf.DUMMYFUNCTION("LET( 賽道, ""PT:9T"", 路線, ""DH"", 系統, ""CVS"", 原始, FILTER('歷史紀錄'!E2:H1168, '歷史紀錄'!B2:B1168=賽道, '歷史紀錄'!C2:C1168=路線, '歷史紀錄'!I2:I1168=系統), 排序後, SORT(原始, 2, TRUE), 玩家, INDEX(排序後,,1), 唯一玩家, UNIQUE(玩家), 結果, MAP(唯一玩家, LAMBDA(p, INDEX(FILT"&"ER(排序後, INDEX(排序後,,1)=p),1,0) )), 表頭, {""Player玩家"",""Time時間"",""Car車種"",""Platform平台""}, VSTACK(表頭, 結果) ) "),"Player玩家") -> Player玩家 | R3: =IFERROR(__xludf.DUMMYFUNCTION("""COMPUTED_VALUE"""),"Time時間") -> Time時間 | S3: =IFERROR(__xludf.DUMMYFUNCTION("""COMPUTED_VALUE"""),"Car車種") -> Car車種 | T3: =IFERROR(__xludf.DUMMYFUNCTION("""COMPUTED_VALUE"""),"Platform平台") -> Platform平台 | U3: Player玩家 | V3: Time時間 | W3: Car車種 | X3: Platform平台
A4: =IFERROR(__xludf.DUMMYFUNCTION("""COMPUTED_VALUE"""),"Lolidia") -> Lolidia | B4: =IFERROR(__xludf.DUMMYFUNCTION("""COMPUTED_VALUE"""),0.0023936574074074073) -> 0.0023936574 | C4: =IFERROR(__xludf.DUMMYFUNCTION("""COMPUTED_VALUE"""),"AE86T-V2") -> AE86T-V2 | D4: =IFERROR(__xludf.DUMMYFUNCTION("""COMPUTED_VALUE"""),"PCVR") -> PCVR | E4: =IFERROR(__xludf.DUMMYFUNCTION("""COMPUTED_VALUE"""),"Lolidia") -> Lolidia | F4: =IFERROR(__xludf.DUMMYFUNCTION("""COMPUTED_VALUE"""),0.002610914351851852) -> 0.0026109144 | G4: =IFERROR(__xludf.DUMMYFUNCTION("""COMPUTED_VALUE"""),"AE86T-V2") -> AE86T-V2 | H4: =IFERROR(__xludf.DUMMYFUNCTION("""COMPUTED_VALUE"""),"PCVR") -> PCVR | I4: =IFERROR(__xludf.DUMMYFUNCTION("""COMPUTED_VALUE"""),"ねぎたま") -> ねぎたま | J4: =IFERROR(__xludf.DUMMYFUNCTION("""COMPUTED_VALUE"""),0.002542025462962963) -> 0.0025420255 | K4: =IFERROR(__xludf.DUMMYFUNCTION("""COMPUTED_VALUE"""),"X7 RR") -> X7 RR | L4: =IFERROR(__xludf.DUMMYFUNCTION("""COMPUTED_VALUE"""),"PCVR") -> PCVR | M4: =IFERROR(__xludf.DUMMYFUNCTION("""COMPUTED_VALUE"""),"#N/A") -> #N/A | N4: =IFERROR(__xludf.DUMMYFUNCTION("""COMPUTED_VALUE"""),"#N/A") -> #N/A | O4: =IFERROR(__xludf.DUMMYFUNCTION("""COMPUTED_VALUE"""),"#N/A") -> #N/A | P4: =IFERROR(__xludf.DUMMYFUNCTION("""COMPUTED_VALUE"""),"#N/A") -> #N/A | Q4: =IFERROR(__xludf.DUMMYFUNCTION("""COMPUTED_VALUE"""),"MotherEVO") -> MotherEVO | R4: =IFERROR(__xludf.DUMMYFUNCTION("""COMPUTED_VALUE"""),0.0038710300925925926) -> 0.0038710301 | S4: =IFERROR(__xludf.DUMMYFUNCTION("""COMPUTED_VALUE"""),"EVOIII/CE9A") -> EVOIII/CE9A | T4: =IFERROR(__xludf.DUMMYFUNCTION("""COMPUTED_VALUE"""),"PCVR") -> PCVR
A5: =IFERROR(__xludf.DUMMYFUNCTION("""COMPUTED_VALUE"""),"ikuhopen") -> ikuhopen | B5: =IFERROR(__xludf.DUMMYFUNCTION("""COMPUTED_VALUE"""),0.002443599537037037) -> 0.0024435995 | C5: =IFERROR(__xludf.DUMMYFUNCTION("""COMPUTED_VALUE"""),"GR86/ZN8") -> GR86/ZN8 | D5: =IFERROR(__xludf.DUMMYFUNCTION("""COMPUTED_VALUE"""),"PCVR") -> PCVR | E5: =IFERROR(__xludf.DUMMYFUNCTION("""COMPUTED_VALUE"""),"ZihChin") -> ZihChin | F5: =IFERROR(__xludf.DUMMYFUNCTION("""COMPUTED_VALUE"""),0.0027186689814814816) -> 0.002718669 | G5: =IFERROR(__xludf.DUMMYFUNCTION("""COMPUTED_VALUE"""),"GT86/ZN6") -> GT86/ZN6 | H5: =IFERROR(__xludf.DUMMYFUNCTION("""COMPUTED_VALUE"""),"PC") -> PC | I5: =IFERROR(__xludf.DUMMYFUNCTION("""COMPUTED_VALUE"""),"StarRiver Arts") -> StarRiver Arts | J5: =IFERROR(__xludf.DUMMYFUNCTION("""COMPUTED_VALUE"""),0.0034108796296296296) -> 0.0034108796 | K5: =IFERROR(__xludf.DUMMYFUNCTION("""COMPUTED_VALUE"""),"Karin 96") -> Karin 96 | L5: =IFERROR(__xludf.DUMMYFUNCTION("""COMPUTED_VALUE"""),"PC") -> PC | Q5: =IFERROR(__xludf.DUMMYFUNCTION("""COMPUTED_VALUE"""),"Lolidia") -> Lolidia | R5: =IFERROR(__xludf.DUMMYFUNCTION("""COMPUTED_VALUE"""),0.004538715277777778) -> 0.0045387153 | S5: =IFERROR(__xludf.DUMMYFUNCTION("""COMPUTED_VALUE"""),"SampleCar") -> SampleCar | T5: =IFERROR(__xludf.DUMMYFUNCTION("""COMPUTED_VALUE"""),"PCVR") -> PCVR
A6: =IFERROR(__xludf.DUMMYFUNCTION("""COMPUTED_VALUE"""),"菲娜 希琉絲") -> 菲娜 希琉絲 | B6: =IFERROR(__xludf.DUMMYFUNCTION("""COMPUTED_VALUE"""),0.0024633449074074076) -> 0.0024633449 | C6: =IFERROR(__xludf.DUMMYFUNCTION("""COMPUTED_VALUE"""),"AE86T-V2") -> AE86T-V2 | D6: =IFERROR(__xludf.DUMMYFUNCTION("""COMPUTED_VALUE"""),"PCVR") -> PCVR | E6: =IFERROR(__xludf.DUMMYFUNCTION("""COMPUTED_VALUE"""),"StarRiver Arts") -> StarRiver Arts | F6: =IFERROR(__xludf.DUMMYFUNCTION("""COMPUTED_VALUE"""),0.0029733796296296296) -> 0.0029733796 | G6: =IFERROR(__xludf.DUMMYFUNCTION("""COMPUTED_VALUE"""),"EVOIV/CN9A") -> EVOIV/CN9A | H6: =IFERROR(__xludf.DUMMYFUNCTION("""COMPUTED_VALUE"""),"PC") -> PC | I6: =IFERROR(__xludf.DUMMYFUNCTION("""COMPUTED_VALUE"""),"Test Driver") -> Test Driver | J6: =IFERROR(__xludf.DUMMYFUNCTION("""COMPUTED_VALUE"""),0.006944444444444444) -> 0.0069444444 | K6: =IFERROR(__xludf.DUMMYFUNCTION("""COMPUTED_VALUE"""),"Comet Custom") -> Comet Custom | Q6: =IFERROR(__xludf.DUMMYFUNCTION("""COMPUTED_VALUE"""),"Lireth") -> Lireth | R6: =IFERROR(__xludf.DUMMYFUNCTION("""COMPUTED_VALUE"""),0.0047026041666666666) -> 0.0047026042 | S6: =IFERROR(__xludf.DUMMYFUNCTION("""COMPUTED_VALUE"""),"SampleCar") -> SampleCar | T6: =IFERROR(__xludf.DUMMYFUNCTION("""COMPUTED_VALUE"""),"PCVR") -> PCVR
A7: =IFERROR(__xludf.DUMMYFUNCTION("""COMPUTED_VALUE"""),"『Sigma』") -> 『Sigma』 | B7: =IFERROR(__xludf.DUMMYFUNCTION("""COMPUTED_VALUE"""),0.002495983796296296) -> 0.0024959838 | C7: =IFERROR(__xludf.DUMMYFUNCTION("""COMPUTED_VALUE"""),"AE86T-V2") -> AE86T-V2 | D7: =IFERROR(__xludf.DUMMYFUNCTION("""COMPUTED_VALUE"""),"PC") -> PC | E7: =IFERROR(__xludf.DUMMYFUNCTION("""COMPUTED_VALUE"""),"Test Driver") -> Test Driver | F7: =IFERROR(__xludf.DUMMYFUNCTION("""COMPUTED_VALUE"""),0.006944444444444444) -> 0.0069444444 | G7: =IFERROR(__xludf.DUMMYFUNCTION("""COMPUTED_VALUE"""),"180SX") -> 180SX | Q7: =IFERROR(__xludf.DUMMYFUNCTION("""COMPUTED_VALUE"""),"アビドサスヒカリ") -> アビドサスヒカリ | R7: =IFERROR(__xludf.DUMMYFUNCTION("""COMPUTED_VALUE"""),0.004801944444444445) -> 0.0048019444 | S7: =IFERROR(__xludf.DUMMYFUNCTION("""COMPUTED_VALUE"""),"EVOIII/CE9A") -> EVOIII/CE9A | T7: =IFERROR(__xludf.DUMMYFUNCTION("""COMPUTED_VALUE"""),"PC") -> PC
A8: =IFERROR(__xludf.DUMMYFUNCTION("""COMPUTED_VALUE"""),"Yune") -> Yune | B8: =IFERROR(__xludf.DUMMYFUNCTION("""COMPUTED_VALUE"""),0.0025360763888888885) -> 0.0025360764 | C8: =IFERROR(__xludf.DUMMYFUNCTION("""COMPUTED_VALUE"""),"GC8-F (Impreza)") -> GC8-F (Impreza) | D8: =IFERROR(__xludf.DUMMYFUNCTION("""COMPUTED_VALUE"""),"PC") -> PC | Q8: =IFERROR(__xludf.DUMMYFUNCTION("""COMPUTED_VALUE"""),"Doyakyon") -> Doyakyon | R8: =IFERROR(__xludf.DUMMYFUNCTION("""COMPUTED_VALUE"""),0.004922835648148148) -> 0.0049228356 | S8: =IFERROR(__xludf.DUMMYFUNCTION("""COMPUTED_VALUE"""),"EVOIII/CE9A") -> EVOIII/CE9A | T8: =IFERROR(__xludf.DUMMYFUNCTION("""COMPUTED_VALUE"""),"PCVR") -> PCVR
A9: =IFERROR(__xludf.DUMMYFUNCTION("""COMPUTED_VALUE"""),"Kinokono_Tenka") -> Kinokono_Tenka | B9: =IFERROR(__xludf.DUMMYFUNCTION("""COMPUTED_VALUE"""),0.002562048611111111) -> 0.0025620486 | C9: =IFERROR(__xludf.DUMMYFUNCTION("""COMPUTED_VALUE"""),"EG6 (civic)") -> EG6 (civic) | D9: =IFERROR(__xludf.DUMMYFUNCTION("""COMPUTED_VALUE"""),"PCVR") -> PCVR | Q9: =IFERROR(__xludf.DUMMYFUNCTION("""COMPUTED_VALUE"""),"StarRiver Arts") -> StarRiver Arts | R9: =IFERROR(__xludf.DUMMYFUNCTION("""COMPUTED_VALUE"""),0.0049515856481481485) -> 0.0049515856 | S9: =IFERROR(__xludf.DUMMYFUNCTION("""COMPUTED_VALUE"""),"EVOIII/CE9A") -> EVOIII/CE9A | T9: =IFERROR(__xludf.DUMMYFUNCTION("""COMPUTED_VALUE"""),"PC") -> PC
A10: =IFERROR(__xludf.DUMMYFUNCTION("""COMPUTED_VALUE"""),"Rushia Angel") -> Rushia Angel | B10: =IFERROR(__xludf.DUMMYFUNCTION("""COMPUTED_VALUE"""),0.0025628472222222224) -> 0.0025628472 | C10: =IFERROR(__xludf.DUMMYFUNCTION("""COMPUTED_VALUE"""),"BNR32") -> BNR32 | D10: =IFERROR(__xludf.DUMMYFUNCTION("""COMPUTED_VALUE"""),"PC") -> PC | Q10: =IFERROR(__xludf.DUMMYFUNCTION("""COMPUTED_VALUE"""),"Yukira雪夜") -> Yukira雪夜 | R10: =IFERROR(__xludf.DUMMYFUNCTION("""COMPUTED_VALUE"""),0.008214108796296296) -> 0.0082141088 | S10: =IFERROR(__xludf.DUMMYFUNCTION("""COMPUTED_VALUE"""),"Bus") -> Bus | T10: =IFERROR(__xludf.DUMMYFUNCTION("""COMPUTED_VALUE"""),"PCVR") -> PCVR
A11: =IFERROR(__xludf.DUMMYFUNCTION("""COMPUTED_VALUE"""),"StarRiver Arts") -> StarRiver Arts | B11: =IFERROR(__xludf.DUMMYFUNCTION("""COMPUTED_VALUE"""),0.0025968402777777778) -> 0.0025968403 | C11: =IFERROR(__xludf.DUMMYFUNCTION("""COMPUTED_VALUE"""),"EVOIV/CN9A") -> EVOIV/CN9A | D11: =IFERROR(__xludf.DUMMYFUNCTION("""COMPUTED_VALUE"""),"PC") -> PC
A12: =IFERROR(__xludf.DUMMYFUNCTION("""COMPUTED_VALUE"""),"アビドサスヒカリ") -> アビドサスヒカリ | B12: =IFERROR(__xludf.DUMMYFUNCTION("""COMPUTED_VALUE"""),0.0025991550925925926) -> 0.0025991551 | C12: =IFERROR(__xludf.DUMMYFUNCTION("""COMPUTED_VALUE"""),"S30Z(Nissan Fairlady Z/Devil Z)") -> S30Z(Nissan Fairlady Z/Devil Z) | D12: =IFERROR(__xludf.DUMMYFUNCTION("""COMPUTED_VALUE"""),"PC") -> PC | I12: Momiji Downhill 紅葉坂/下行 | M12: Sekia Hills | Q12: 9Turns Sacc Downhill 九彎十八拐/下行 | U12: 9Turns Sacc Uphill 九彎十八拐/上行
A13: =IFERROR(__xludf.DUMMYFUNCTION("""COMPUTED_VALUE"""),"redfrogss") -> redfrogss | B13: =IFERROR(__xludf.DUMMYFUNCTION("""COMPUTED_VALUE"""),0.00266712962962963) -> 0.0026671296 | C13: =IFERROR(__xludf.DUMMYFUNCTION("""COMPUTED_VALUE"""),"BNR32") -> BNR32 | D13: =IFERROR(__xludf.DUMMYFUNCTION("""COMPUTED_VALUE"""),"PCVR") -> PCVR | I13: =IFERROR(__xludf.DUMMYFUNCTION("LET( 賽道, ""Momiji"", 路線, ""DH"", 系統, ""CVS"", 原始, FILTER('歷史紀錄'!$E$2:H1168, '歷史紀錄'!$B$2:B1168=賽道, '歷史紀錄'!$C$2:C1168=路線, '歷史紀錄'!$I$2:I1168=系統), 排序後, SORT(原始, 2, TRUE), 玩家, INDEX(排序後,,1), 唯一玩家, UNIQUE(玩家), 結果, MAP(唯一玩家, LAMBDA(p, I"&"NDEX(FILTER(排序後, INDEX(排序後,,1)=p),1,0) )), 表頭, {""Player玩家"",""Time時間"",""Car車種"",""Platform平台""}, VSTACK(表頭, 結果) ) "),"Player玩家") -> Player玩家 | J13: =IFERROR(__xludf.DUMMYFUNCTION("""COMPUTED_VALUE"""),"Time時間") -> Time時間 | K13: =IFERROR(__xludf.DUMMYFUNCTION("""COMPUTED_VALUE"""),"Car車種") -> Car車種 | L13: =IFERROR(__xludf.DUMMYFUNCTION("""COMPUTED_VALUE"""),"Platform平台") -> Platform平台 | M13: =IFERROR(__xludf.DUMMYFUNCTION("LET( 賽道, """", 路線, ""DH"", 系統, ""CVS"", 原始, FILTER('歷史紀錄'!E2:H1168, '歷史紀錄'!B2:B1168=賽道, '歷史紀錄'!C2:C1168=路線, '歷史紀錄'!I2:I1168=系統), 排序後, SORT(原始, 2, TRUE), 玩家, INDEX(排序後,,1), 唯一玩家, UNIQUE(玩家), 結果, MAP(唯一玩家, LAMBDA(p, INDEX(FILTER(排序"&"後, INDEX(排序後,,1)=p),1,0) )), 表頭, {""Player玩家"",""Time時間"",""Car車種"",""Platform平台""}, VSTACK(表頭, 結果) ) "),"Player玩家") -> Player玩家 | N13: =IFERROR(__xludf.DUMMYFUNCTION("""COMPUTED_VALUE"""),"Time時間") -> Time時間 | O13: =IFERROR(__xludf.DUMMYFUNCTION("""COMPUTED_VALUE"""),"Car車種") -> Car車種 | P13: =IFERROR(__xludf.DUMMYFUNCTION("""COMPUTED_VALUE"""),"Platform平台") -> Platform平台 | Q13: Player玩家 | R13: Time時間 | S13: Car車種 | T13: Platform平台 | U13: Player玩家 | V13: Time時間 | W13: Car車種 | X13: Platform平台
A14: =IFERROR(__xludf.DUMMYFUNCTION("""COMPUTED_VALUE"""),"LinWu_05") -> LinWu_05 | B14: =IFERROR(__xludf.DUMMYFUNCTION("""COMPUTED_VALUE"""),0.0027110300925925926) -> 0.0027110301 | C14: =IFERROR(__xludf.DUMMYFUNCTION("""COMPUTED_VALUE"""),"GC8-F (Impreza)") -> GC8-F (Impreza) | D14: =IFERROR(__xludf.DUMMYFUNCTION("""COMPUTED_VALUE"""),"PC") -> PC | I14: =IFERROR(__xludf.DUMMYFUNCTION("""COMPUTED_VALUE"""),"Lolidia") -> Lolidia | J14: =IFERROR(__xludf.DUMMYFUNCTION("""COMPUTED_VALUE"""),0.0022057291666666666) -> 0.0022057292 | K14: =IFERROR(__xludf.DUMMYFUNCTION("""COMPUTED_VALUE"""),"Karin 96") -> Karin 96 | L14: =IFERROR(__xludf.DUMMYFUNCTION("""COMPUTED_VALUE"""),"PCVR") -> PCVR | M14: =IFERROR(__xludf.DUMMYFUNCTION("""COMPUTED_VALUE"""),"#N/A") -> #N/A | N14: =IFERROR(__xludf.DUMMYFUNCTION("""COMPUTED_VALUE"""),"#N/A") -> #N/A | O14: =IFERROR(__xludf.DUMMYFUNCTION("""COMPUTED_VALUE"""),"#N/A") -> #N/A | P14: =IFERROR(__xludf.DUMMYFUNCTION("""COMPUTED_VALUE"""),"#N/A") -> #N/A
A15: =IFERROR(__xludf.DUMMYFUNCTION("""COMPUTED_VALUE"""),"Sakanakokokoko") -> Sakanakokokoko | B15: =IFERROR(__xludf.DUMMYFUNCTION("""COMPUTED_VALUE"""),0.003489201388888889) -> 0.0034892014 | C15: =IFERROR(__xludf.DUMMYFUNCTION("""COMPUTED_VALUE"""),"FD3S (RX7)(TT)") -> FD3S (RX7)(TT) | D15: =IFERROR(__xludf.DUMMYFUNCTION("""COMPUTED_VALUE"""),"PC") -> PC | I15: =IFERROR(__xludf.DUMMYFUNCTION("""COMPUTED_VALUE"""),"ねぎたま") -> ねぎたま | J15: =IFERROR(__xludf.DUMMYFUNCTION("""COMPUTED_VALUE"""),0.002222199074074074) -> 0.0022221991 | K15: =IFERROR(__xludf.DUMMYFUNCTION("""COMPUTED_VALUE"""),"X7 RR") -> X7 RR | L15: =IFERROR(__xludf.DUMMYFUNCTION("""COMPUTED_VALUE"""),"PCVR") -> PCVR
A16: =IFERROR(__xludf.DUMMYFUNCTION("""COMPUTED_VALUE"""),"Yuanji Deca") -> Yuanji Deca | B16: =IFERROR(__xludf.DUMMYFUNCTION("""COMPUTED_VALUE"""),0.003531770833333333) -> 0.0035317708 | C16: =IFERROR(__xludf.DUMMYFUNCTION("""COMPUTED_VALUE"""),"AE86T-V2") -> AE86T-V2 | D16: =IFERROR(__xludf.DUMMYFUNCTION("""COMPUTED_VALUE"""),"PC") -> PC | I16: =IFERROR(__xludf.DUMMYFUNCTION("""COMPUTED_VALUE"""),"BannRaven") -> BannRaven | J16: =IFERROR(__xludf.DUMMYFUNCTION("""COMPUTED_VALUE"""),0.002424664351851852) -> 0.0024246644 | K16: =IFERROR(__xludf.DUMMYFUNCTION("""COMPUTED_VALUE"""),"Revolution VIII") -> Revolution VIII | L16: =IFERROR(__xludf.DUMMYFUNCTION("""COMPUTED_VALUE"""),"PCVR") -> PCVR
A17: =IFERROR(__xludf.DUMMYFUNCTION("""COMPUTED_VALUE"""),"Test Driver") -> Test Driver | B17: =IFERROR(__xludf.DUMMYFUNCTION("""COMPUTED_VALUE"""),0.006944444444444444) -> 0.0069444444 | C17: =IFERROR(__xludf.DUMMYFUNCTION("""COMPUTED_VALUE"""),"AE86L") -> AE86L | I17: =IFERROR(__xludf.DUMMYFUNCTION("""COMPUTED_VALUE"""),"VRCGPaul") -> VRCGPaul | J17: =IFERROR(__xludf.DUMMYFUNCTION("""COMPUTED_VALUE"""),0.002528541666666667) -> 0.0025285417 | K17: =IFERROR(__xludf.DUMMYFUNCTION("""COMPUTED_VALUE"""),"Emrydes") -> Emrydes | L17: =IFERROR(__xludf.DUMMYFUNCTION("""COMPUTED_VALUE"""),"PCVR") -> PCVR
I18: =IFERROR(__xludf.DUMMYFUNCTION("""COMPUTED_VALUE"""),"LinWu_05") -> LinWu_05 | J18: =IFERROR(__xludf.DUMMYFUNCTION("""COMPUTED_VALUE"""),0.0029710763888888894) -> 0.0029710764 | K18: =IFERROR(__xludf.DUMMYFUNCTION("""COMPUTED_VALUE"""),"NA1 (NSX)") -> NA1 (NSX) | L18: =IFERROR(__xludf.DUMMYFUNCTION("""COMPUTED_VALUE"""),"PC") -> PC
I19: =IFERROR(__xludf.DUMMYFUNCTION("""COMPUTED_VALUE"""),"StarRiver Arts") -> StarRiver Arts | J19: =IFERROR(__xludf.DUMMYFUNCTION("""COMPUTED_VALUE"""),0.0031942476851851854) -> 0.0031942477 | K19: =IFERROR(__xludf.DUMMYFUNCTION("""COMPUTED_VALUE"""),"Highline TT") -> Highline TT | L19: =IFERROR(__xludf.DUMMYFUNCTION("""COMPUTED_VALUE"""),"PC") -> PC | Q19: WuLing CVS Downhill 武嶺/下行 | U19: WuLing CVS Uphill 武嶺/上行
I20: =IFERROR(__xludf.DUMMYFUNCTION("""COMPUTED_VALUE"""),"Rushia Angel") -> Rushia Angel | J20: =IFERROR(__xludf.DUMMYFUNCTION("""COMPUTED_VALUE"""),0.003328981481481482) -> 0.0033289815 | K20: =IFERROR(__xludf.DUMMYFUNCTION("""COMPUTED_VALUE"""),"Emrydes") -> Emrydes | L20: =IFERROR(__xludf.DUMMYFUNCTION("""COMPUTED_VALUE"""),"PC") -> PC | Q20: =IFERROR(__xludf.DUMMYFUNCTION("LET( 賽道, ""WuLing"", 路線, ""DH"", 系統, ""CVS"", 原始, FILTER('歷史紀錄'!E2:H1168, '歷史紀錄'!B2:B1168=賽道, '歷史紀錄'!C2:C1168=路線, '歷史紀錄'!I2:I1168=系統), 排序後, SORT(原始, 2, TRUE), 玩家, INDEX(排序後,,1), 唯一玩家, UNIQUE(玩家), 結果, MAP(唯一玩家, LAMBDA(p, INDEX(FIL"&"TER(排序後, INDEX(排序後,,1)=p),1,0) )), 表頭, {""Player玩家"",""Time時間"",""Car車種"",""Platform平台""}, VSTACK(表頭, 結果) ) "),"Player玩家") -> Player玩家 | R20: =IFERROR(__xludf.DUMMYFUNCTION("""COMPUTED_VALUE"""),"Time時間") -> Time時間 | S20: =IFERROR(__xludf.DUMMYFUNCTION("""COMPUTED_VALUE"""),"Car車種") -> Car車種 | T20: =IFERROR(__xludf.DUMMYFUNCTION("""COMPUTED_VALUE"""),"Platform平台") -> Platform平台 | U20: =IFERROR(__xludf.DUMMYFUNCTION("LET( 賽道, ""WuLing"", 路線, ""UH"", 系統, ""CVS"", 原始, FILTER('歷史紀錄'!E2:H1168, '歷史紀錄'!B2:B1168=賽道, '歷史紀錄'!C2:C1168=路線, '歷史紀錄'!I2:I1168=系統), 排序後, SORT(原始, 2, TRUE), 玩家, INDEX(排序後,,1), 唯一玩家, UNIQUE(玩家), 結果, MAP(唯一玩家, LAMBDA(p, INDEX(FIL"&"TER(排序後, INDEX(排序後,,1)=p),1,0) )), 表頭, {""Player玩家"",""Time時間"",""Car車種"",""Platform平台""}, VSTACK(表頭, 結果) ) "),"Player玩家") -> Player玩家 | V20: =IFERROR(__xludf.DUMMYFUNCTION("""COMPUTED_VALUE"""),"Time時間") -> Time時間 | W20: =IFERROR(__xludf.DUMMYFUNCTION("""COMPUTED_VALUE"""),"Car車種") -> Car車種 | X20: =IFERROR(__xludf.DUMMYFUNCTION("""COMPUTED_VALUE"""),"Platform平台") -> Platform平台
I21: =IFERROR(__xludf.DUMMYFUNCTION("""COMPUTED_VALUE"""),"Test Driver") -> Test Driver | J21: =IFERROR(__xludf.DUMMYFUNCTION("""COMPUTED_VALUE"""),0.006944444444444444) -> 0.0069444444 | K21: =IFERROR(__xludf.DUMMYFUNCTION("""COMPUTED_VALUE"""),"Revolution VIII") -> Revolution VIII | Q21: =IFERROR(__xludf.DUMMYFUNCTION("""COMPUTED_VALUE"""),"#N/A") -> #N/A | R21: =IFERROR(__xludf.DUMMYFUNCTION("""COMPUTED_VALUE"""),"#N/A") -> #N/A | S21: =IFERROR(__xludf.DUMMYFUNCTION("""COMPUTED_VALUE"""),"#N/A") -> #N/A | T21: =IFERROR(__xludf.DUMMYFUNCTION("""COMPUTED_VALUE"""),"#N/A") -> #N/A | U21: =IFERROR(__xludf.DUMMYFUNCTION("""COMPUTED_VALUE"""),"#N/A") -> #N/A | V21: =IFERROR(__xludf.DUMMYFUNCTION("""COMPUTED_VALUE"""),"#N/A") -> #N/A | W21: =IFERROR(__xludf.DUMMYFUNCTION("""COMPUTED_VALUE"""),"#N/A") -> #N/A | X21: =IFERROR(__xludf.DUMMYFUNCTION("""COMPUTED_VALUE"""),"#N/A") -> #N/A
I22: =IFERROR(__xludf.DUMMYFUNCTION("""COMPUTED_VALUE"""),"MrValentine") -> MrValentine | J22: =IFERROR(__xludf.DUMMYFUNCTION("""COMPUTED_VALUE"""),0.0078115393518518525) -> 0.0078115394 | K22: =IFERROR(__xludf.DUMMYFUNCTION("""COMPUTED_VALUE"""),"Comet Custom") -> Comet Custom | L22: =IFERROR(__xludf.DUMMYFUNCTION("""COMPUTED_VALUE"""),"PC") -> PC
A25: Akina UNLIMITED Downhill秋名 無限/下行 | E25: Akina UNLIMITED Uphill秋名 無限/上行 | Q25: StarSight Touge Downhill觀星山/下行 | U25: StarSight Touge Uphill觀星山/上行
A26: =IFERROR(__xludf.DUMMYFUNCTION("LET( 賽道, ""AkinaUN"", 路線, ""DH"", 系統, ""Sacc"", 原始, FILTER('歷史紀錄'!$E$2:$H1168, '歷史紀錄'!$B$2:$B1168=賽道, '歷史紀錄'!$C$2:$C1168=路線, '歷史紀錄'!$I$2:$I1168=系統), 排序後, SORT(原始, 2, TRUE), 玩家, INDEX(排序後,,1), 唯一玩家, UNIQUE(玩家), 結果, MAP(唯一玩家, LAMBDA(p, "&" INDEX(FILTER(排序後, INDEX(排序後,,1)=p),1,0) )), 表頭, {""Player玩家"",""Time時間"",""Car車種"",""Platform平台""}, VSTACK(表頭, 結果) ) "),"Player玩家") -> Player玩家 | B26: =IFERROR(__xludf.DUMMYFUNCTION("""COMPUTED_VALUE"""),"Time時間") -> Time時間 | C26: =IFERROR(__xludf.DUMMYFUNCTION("""COMPUTED_VALUE"""),"Car車種") -> Car車種 | D26: =IFERROR(__xludf.DUMMYFUNCTION("""COMPUTED_VALUE"""),"Platform平台") -> Platform平台 | E26: =IFERROR(__xludf.DUMMYFUNCTION("LET( 賽道, ""AkinaUN"", 路線, ""UH"", 系統, ""Sacc"", 原始, FILTER('歷史紀錄'!$E$2:$H1168, '歷史紀錄'!$B$2:$B1168=賽道, '歷史紀錄'!$C$2:$C1168=路線, '歷史紀錄'!$I$2:$I1168=系統), 排序後, SORT(原始, 2, TRUE), 玩家, INDEX(排序後,,1), 唯一玩家, UNIQUE(玩家), 結果, MAP(唯一玩家, LAMBDA(p, "&" INDEX(FILTER(排序後, INDEX(排序後,,1)=p),1,0) )), 表頭, {""Player玩家"",""Time時間"",""Car車種"",""Platform平台""}, VSTACK(表頭, 結果) ) "),"Player玩家") -> Player玩家 | F26: =IFERROR(__xludf.DUMMYFUNCTION("""COMPUTED_VALUE"""),"Time時間") -> Time時間 | G26: =IFERROR(__xludf.DUMMYFUNCTION("""COMPUTED_VALUE"""),"Car車種") -> Car車種 | H26: =IFERROR(__xludf.DUMMYFUNCTION("""COMPUTED_VALUE"""),"Platform平台") -> Platform平台 | I26: Bihoku Highland Circuit | Q26: =IFERROR(__xludf.DUMMYFUNCTION("LET( 賽道, ""StarSight"", 路線, ""DH"", 系統, ""CVS"", 原始, FILTER('歷史紀錄'!E8:H1168, '歷史紀錄'!B8:B1168=賽道, '歷史紀錄'!C8:C1168=路線, '歷史紀錄'!I8:I1168=系統), 排序後, SORT(原始, 2, TRUE), 玩家, INDEX(排序後,,1), 唯一玩家, UNIQUE(玩家), 結果, MAP(唯一玩家, LAMBDA(p, INDEX("&"FILTER(排序後, INDEX(排序後,,1)=p),1,0) )), 表頭, {""Player玩家"",""Time時間"",""Car車種"",""Platform平台""}, VSTACK(表頭, 結果) ) "),"Player玩家") -> Player玩家 | R26: =IFERROR(__xludf.DUMMYFUNCTION("""COMPUTED_VALUE"""),"Time時間") -> Time時間 | S26: =IFERROR(__xludf.DUMMYFUNCTION("""COMPUTED_VALUE"""),"Car車種") -> Car車種 | T26: =IFERROR(__xludf.DUMMYFUNCTION("""COMPUTED_VALUE"""),"Platform平台") -> Platform平台 | U26: =IFERROR(__xludf.DUMMYFUNCTION("LET( 賽道, ""StarSight"", 路線, ""UH"", 系統, ""CVS"", 原始, FILTER('歷史紀錄'!I8:N1168, '歷史紀錄'!F8:F1168=賽道, '歷史紀錄'!G8:G1168=路線, '歷史紀錄'!O8:O1168=系統), 排序後, SORT(原始, 2, TRUE), 玩家, INDEX(排序後,,1), 唯一玩家, UNIQUE(玩家), 結果, MAP(唯一玩家, LAMBDA(p, INDEX("&"FILTER(排序後, INDEX(排序後,,1)=p),1,0) )), 表頭, {""Player玩家"",""Time時間"",""Car車種"",""Platform平台""}, VSTACK(表頭, 結果) ) "),"Player玩家") -> Player玩家 | V26: =IFERROR(__xludf.DUMMYFUNCTION("""COMPUTED_VALUE"""),"Time時間") -> Time時間 | W26: =IFERROR(__xludf.DUMMYFUNCTION("""COMPUTED_VALUE"""),"Car車種") -> Car車種 | X26: =IFERROR(__xludf.DUMMYFUNCTION("""COMPUTED_VALUE"""),"Platform平台") -> Platform平台
A27: =IFERROR(__xludf.DUMMYFUNCTION("""COMPUTED_VALUE"""),"Lolidia") -> Lolidia | B27: =IFERROR(__xludf.DUMMYFUNCTION("""COMPUTED_VALUE"""),0.0025432175925925926) -> 0.0025432176 | C27: =IFERROR(__xludf.DUMMYFUNCTION("""COMPUTED_VALUE"""),"AE86T") -> AE86T | D27: =IFERROR(__xludf.DUMMYFUNCTION("""COMPUTED_VALUE"""),"PCVR") -> PCVR | E27: =IFERROR(__xludf.DUMMYFUNCTION("""COMPUTED_VALUE"""),"Test Driver") -> Test Driver | F27: =IFERROR(__xludf.DUMMYFUNCTION("""COMPUTED_VALUE"""),0.006944444444444444) -> 0.0069444444 | G27: =IFERROR(__xludf.DUMMYFUNCTION("""COMPUTED_VALUE"""),"AE86T-V2") -> AE86T-V2 | I27: =IFERROR(__xludf.DUMMYFUNCTION("LET( 賽道, """", 路線, ""DH"", 系統, ""CVS"", 原始, FILTER('歷史紀錄'!$E$2:H1168, '歷史紀錄'!$B$2:B1168=賽道, '歷史紀錄'!$C$2:C1168=路線, '歷史紀錄'!$I$2:I1168=系統), 排序後, SORT(原始, 2, TRUE), 玩家, INDEX(排序後,,1), 唯一玩家, UNIQUE(玩家), 結果, MAP(唯一玩家, LAMBDA(p, INDEX(F"&"ILTER(排序後, INDEX(排序後,,1)=p),1,0) )), 表頭, {""Player玩家"",""Time時間"",""Car車種"",""Platform平台""}, VSTACK(表頭, 結果) ) "),"Player玩家") -> Player玩家 | J27: =IFERROR(__xludf.DUMMYFUNCTION("""COMPUTED_VALUE"""),"Time時間") -> Time時間 | K27: =IFERROR(__xludf.DUMMYFUNCTION("""COMPUTED_VALUE"""),"Car車種") -> Car車種 | L27: =IFERROR(__xludf.DUMMYFUNCTION("""COMPUTED_VALUE"""),"Platform平台") -> Platform平台 | M27: =IFERROR(__xludf.DUMMYFUNCTION("LET( 賽道, """", 路線, ""DH"", 系統, ""CVS"", 原始, FILTER('歷史紀錄'!E16:H1168, '歷史紀錄'!B16:B1168=賽道, '歷史紀錄'!C16:C1168=路線, '歷史紀錄'!I16:I1168=系統), 排序後, SORT(原始, 2, TRUE), 玩家, INDEX(排序後,,1), 唯一玩家, UNIQUE(玩家), 結果, MAP(唯一玩家, LAMBDA(p, INDEX(FILTE"&"R(排序後, INDEX(排序後,,1)=p),1,0) )), 表頭, {""Player玩家"",""Time時間"",""Car車種"",""Platform平台""}, VSTACK(表頭, 結果) ) "),"Player玩家") -> Player玩家 | N27: =IFERROR(__xludf.DUMMYFUNCTION("""COMPUTED_VALUE"""),"Time時間") -> Time時間 | O27: =IFERROR(__xludf.DUMMYFUNCTION("""COMPUTED_VALUE"""),"Car車種") -> Car車種 | P27: =IFERROR(__xludf.DUMMYFUNCTION("""COMPUTED_VALUE"""),"Platform平台") -> Platform平台 | Q27: =IFERROR(__xludf.DUMMYFUNCTION("""COMPUTED_VALUE"""),"Lolidia") -> Lolidia | R27: =IFERROR(__xludf.DUMMYFUNCTION("""COMPUTED_VALUE"""),0.0010182638888888889) -> 0.0010182639 | S27: =IFERROR(__xludf.DUMMYFUNCTION("""COMPUTED_VALUE"""),"EVO3") -> EVO3 | T27: =IFERROR(__xludf.DUMMYFUNCTION("""COMPUTED_VALUE"""),"PCVR") -> PCVR | U27: =IFERROR(__xludf.DUMMYFUNCTION("""COMPUTED_VALUE"""),"#N/A") -> #N/A | V27: =IFERROR(__xludf.DUMMYFUNCTION("""COMPUTED_VALUE"""),"#N/A") -> #N/A | W27: =IFERROR(__xludf.DUMMYFUNCTION("""COMPUTED_VALUE"""),"#N/A") -> #N/A | X27: =IFERROR(__xludf.DUMMYFUNCTION("""COMPUTED_VALUE"""),"#N/A") -> #N/A
A28: =IFERROR(__xludf.DUMMYFUNCTION("""COMPUTED_VALUE"""),"ikuhopen") -> ikuhopen | B28: =IFERROR(__xludf.DUMMYFUNCTION("""COMPUTED_VALUE"""),0.0025631944444444448) -> 0.0025631944 | C28: =IFERROR(__xludf.DUMMYFUNCTION("""COMPUTED_VALUE"""),"GT86/ZN6") -> GT86/ZN6 | D28: =IFERROR(__xludf.DUMMYFUNCTION("""COMPUTED_VALUE"""),"PCVR") -> PCVR | I28: =IFERROR(__xludf.DUMMYFUNCTION("""COMPUTED_VALUE"""),"#N/A") -> #N/A | J28: =IFERROR(__xludf.DUMMYFUNCTION("""COMPUTED_VALUE"""),"#N/A") -> #N/A | K28: =IFERROR(__xludf.DUMMYFUNCTION("""COMPUTED_VALUE"""),"#N/A") -> #N/A | L28: =IFERROR(__xludf.DUMMYFUNCTION("""COMPUTED_VALUE"""),"#N/A") -> #N/A | M28: =IFERROR(__xludf.DUMMYFUNCTION("""COMPUTED_VALUE"""),"#N/A") -> #N/A | N28: =IFERROR(__xludf.DUMMYFUNCTION("""COMPUTED_VALUE"""),"#N/A") -> #N/A | O28: =IFERROR(__xludf.DUMMYFUNCTION("""COMPUTED_VALUE"""),"#N/A") -> #N/A | P28: =IFERROR(__xludf.DUMMYFUNCTION("""COMPUTED_VALUE"""),"#N/A") -> #N/A | Q28: =IFERROR(__xludf.DUMMYFUNCTION("""COMPUTED_VALUE"""),"ねぎたま") -> ねぎたま | R28: =IFERROR(__xludf.DUMMYFUNCTION("""COMPUTED_VALUE"""),0.001018287037037037) -> 0.001018287 | S28: =IFERROR(__xludf.DUMMYFUNCTION("""COMPUTED_VALUE"""),"EVO3") -> EVO3 | T28: =IFERROR(__xludf.DUMMYFUNCTION("""COMPUTED_VALUE"""),"PCVR") -> PCVR
A29: =IFERROR(__xludf.DUMMYFUNCTION("""COMPUTED_VALUE"""),"StarRiver Arts") -> StarRiver Arts | B29: =IFERROR(__xludf.DUMMYFUNCTION("""COMPUTED_VALUE"""),0.0029052893518518516) -> 0.0029052894 | C29: =IFERROR(__xludf.DUMMYFUNCTION("""COMPUTED_VALUE"""),"Comfort") -> Comfort | D29: =IFERROR(__xludf.DUMMYFUNCTION("""COMPUTED_VALUE"""),"PC") -> PC | Q29: =IFERROR(__xludf.DUMMYFUNCTION("""COMPUTED_VALUE"""),"Light_Spirit") -> Light_Spirit | R29: =IFERROR(__xludf.DUMMYFUNCTION("""COMPUTED_VALUE"""),0.0010786226851851853) -> 0.0010786227 | S29: =IFERROR(__xludf.DUMMYFUNCTION("""COMPUTED_VALUE"""),"Macchiato") -> Macchiato | T29: =IFERROR(__xludf.DUMMYFUNCTION("""COMPUTED_VALUE"""),"PCVR") -> PCVR
A30: =IFERROR(__xludf.DUMMYFUNCTION("""COMPUTED_VALUE"""),"ZihChin") -> ZihChin | B30: =IFERROR(__xludf.DUMMYFUNCTION("""COMPUTED_VALUE"""),0.003164930555555556) -> 0.0031649306 | C30: =IFERROR(__xludf.DUMMYFUNCTION("""COMPUTED_VALUE"""),"HCR32") -> HCR32 | D30: =IFERROR(__xludf.DUMMYFUNCTION("""COMPUTED_VALUE"""),"PC") -> PC | Q30: =IFERROR(__xludf.DUMMYFUNCTION("""COMPUTED_VALUE"""),"StarRiver Arts") -> StarRiver Arts | R30: =IFERROR(__xludf.DUMMYFUNCTION("""COMPUTED_VALUE"""),0.0010796643518518518) -> 0.0010796644 | S30: =IFERROR(__xludf.DUMMYFUNCTION("""COMPUTED_VALUE"""),"EVO3") -> EVO3 | T30: =IFERROR(__xludf.DUMMYFUNCTION("""COMPUTED_VALUE"""),"PC") -> PC
A31: =IFERROR(__xludf.DUMMYFUNCTION("""COMPUTED_VALUE"""),"Test Driver") -> Test Driver | B31: =IFERROR(__xludf.DUMMYFUNCTION("""COMPUTED_VALUE"""),0.006944444444444444) -> 0.0069444444 | C31: =IFERROR(__xludf.DUMMYFUNCTION("""COMPUTED_VALUE"""),"2000GT") -> 2000GT | Q31: =IFERROR(__xludf.DUMMYFUNCTION("""COMPUTED_VALUE"""),"アビドサスヒカリ") -> アビドサスヒカリ | R31: =IFERROR(__xludf.DUMMYFUNCTION("""COMPUTED_VALUE"""),0.0010816319444444445) -> 0.0010816319 | S31: =IFERROR(__xludf.DUMMYFUNCTION("""COMPUTED_VALUE"""),"EVO3") -> EVO3 | T31: =IFERROR(__xludf.DUMMYFUNCTION("""COMPUTED_VALUE"""),"PCVR") -> PCVR
Q32: =IFERROR(__xludf.DUMMYFUNCTION("""COMPUTED_VALUE"""),"Chrno_C") -> Chrno_C | R32: =IFERROR(__xludf.DUMMYFUNCTION("""COMPUTED_VALUE"""),0.0010866782407407407) -> 0.0010866782 | S32: =IFERROR(__xludf.DUMMYFUNCTION("""COMPUTED_VALUE"""),"EVO3") -> EVO3 | T32: =IFERROR(__xludf.DUMMYFUNCTION("""COMPUTED_VALUE"""),"PCVR") -> PCVR
A33: Myogi Downhill妙義/下行 (Arcade Stage) | E33: Myogi Uphill妙義/上行 (Arcade Stage) | Q33: =IFERROR(__xludf.DUMMYFUNCTION("""COMPUTED_VALUE"""),"Yangtao") -> Yangtao | R33: =IFERROR(__xludf.DUMMYFUNCTION("""COMPUTED_VALUE"""),0.0011427430555555555) -> 0.0011427431 | S33: =IFERROR(__xludf.DUMMYFUNCTION("""COMPUTED_VALUE"""),"LapinTuned") -> LapinTuned | T33: =IFERROR(__xludf.DUMMYFUNCTION("""COMPUTED_VALUE"""),"PCVR") -> PCVR
A34: =IFERROR(__xludf.DUMMYFUNCTION("LET( 賽道, ""Myogi (ASV)"", 路線, ""DH"", 系統, ""Sacc"", 原始, FILTER('歷史紀錄'!$E$2:$H1168, '歷史紀錄'!$B$2:$B1168=賽道, '歷史紀錄'!$C$2:$C1168=路線, '歷史紀錄'!$I$2:$I1168=系統), 排序後, SORT(原始, 2, TRUE), 玩家, INDEX(排序後,,1), 唯一玩家, UNIQUE(玩家), 結果, MAP(唯一玩家, LAMBDA("&"p, INDEX(FILTER(排序後, INDEX(排序後,,1)=p),1,0) )), 表頭, {""Player玩家"",""Time時間"",""Car車種"",""Platform平台""}, VSTACK(表頭, 結果) ) "),"Player玩家") -> Player玩家 | B34: =IFERROR(__xludf.DUMMYFUNCTION("""COMPUTED_VALUE"""),"Time時間") -> Time時間 | C34: =IFERROR(__xludf.DUMMYFUNCTION("""COMPUTED_VALUE"""),"Car車種") -> Car車種 | D34: =IFERROR(__xludf.DUMMYFUNCTION("""COMPUTED_VALUE"""),"Platform平台") -> Platform平台 | E34: =IFERROR(__xludf.DUMMYFUNCTION("LET( 賽道, ""Myogi (ASV)"", 路線, ""UH"", 系統, ""Sacc"", 原始, FILTER('歷史紀錄'!$E$2:$H1168, '歷史紀錄'!$B$2:$B1168=賽道, '歷史紀錄'!$C$2:$C1168=路線, '歷史紀錄'!$I$2:$I1168=系統), 排序後, SORT(原始, 2, TRUE), 玩家, INDEX(排序後,,1), 唯一玩家, UNIQUE(玩家), 結果, MAP(唯一玩家, LAMBDA("&"p, INDEX(FILTER(排序後, INDEX(排序後,,1)=p),1,0) )), 表頭, {""Player玩家"",""Time時間"",""Car車種"",""Platform平台""}, VSTACK(表頭, 結果) ) "),"Player玩家") -> Player玩家 | F34: =IFERROR(__xludf.DUMMYFUNCTION("""COMPUTED_VALUE"""),"Time時間") -> Time時間 | G34: =IFERROR(__xludf.DUMMYFUNCTION("""COMPUTED_VALUE"""),"Car車種") -> Car車種 | H34: =IFERROR(__xludf.DUMMYFUNCTION("""COMPUTED_VALUE"""),"Platform平台") -> Platform平台 | I34: =IFERROR(__xludf.DUMMYFUNCTION("LET( 賽道, """", 路線, ""DH"", 系統, ""CVS"", 原始, FILTER('歷史紀錄'!$E$2:H1168, '歷史紀錄'!$B$2:B1168=賽道, '歷史紀錄'!$C$2:C1168=路線, '歷史紀錄'!$I$2:I1168=系統), 排序後, SORT(原始, 2, TRUE), 玩家, INDEX(排序後,,1), 唯一玩家, UNIQUE(玩家), 結果, MAP(唯一玩家, LAMBDA(p, INDEX(F"&"ILTER(排序後, INDEX(排序後,,1)=p),1,0) )), 表頭, {""Player玩家"",""Time時間"",""Car車種"",""Platform平台""}, VSTACK(表頭, 結果) ) "),"Player玩家") -> Player玩家 | J34: =IFERROR(__xludf.DUMMYFUNCTION("""COMPUTED_VALUE"""),"Time時間") -> Time時間 | K34: =IFERROR(__xludf.DUMMYFUNCTION("""COMPUTED_VALUE"""),"Car車種") -> Car車種 | L34: =IFERROR(__xludf.DUMMYFUNCTION("""COMPUTED_VALUE"""),"Platform平台") -> Platform平台 | M34: =IFERROR(__xludf.DUMMYFUNCTION("LET( 賽道, """", 路線, ""DH"", 系統, ""CVS"", 原始, FILTER('歷史紀錄'!E22:H1168, '歷史紀錄'!B22:B1168=賽道, '歷史紀錄'!C22:C1168=路線, '歷史紀錄'!I22:I1168=系統), 排序後, SORT(原始, 2, TRUE), 玩家, INDEX(排序後,,1), 唯一玩家, UNIQUE(玩家), 結果, MAP(唯一玩家, LAMBDA(p, INDEX(FILTE"&"R(排序後, INDEX(排序後,,1)=p),1,0) )), 表頭, {""Player玩家"",""Time時間"",""Car車種"",""Platform平台""}, VSTACK(表頭, 結果) ) "),"Player玩家") -> Player玩家 | N34: =IFERROR(__xludf.DUMMYFUNCTION("""COMPUTED_VALUE"""),"Time時間") -> Time時間 | O34: =IFERROR(__xludf.DUMMYFUNCTION("""COMPUTED_VALUE"""),"Car車種") -> Car車種 | P34: =IFERROR(__xludf.DUMMYFUNCTION("""COMPUTED_VALUE"""),"Platform平台") -> Platform平台 | Q34: =IFERROR(__xludf.DUMMYFUNCTION("""COMPUTED_VALUE"""),"LinWu_05") -> LinWu_05 | R34: =IFERROR(__xludf.DUMMYFUNCTION("""COMPUTED_VALUE"""),0.0011741898148148148) -> 0.0011741898 | S34: =IFERROR(__xludf.DUMMYFUNCTION("""COMPUTED_VALUE"""),"Macchiato") -> Macchiato | T34: =IFERROR(__xludf.DUMMYFUNCTION("""COMPUTED_VALUE"""),"PC") -> PC
A35: =IFERROR(__xludf.DUMMYFUNCTION("""COMPUTED_VALUE"""),"Lolidia") -> Lolidia | B35: =IFERROR(__xludf.DUMMYFUNCTION("""COMPUTED_VALUE"""),0.002172326388888889) -> 0.0021723264 | C35: =IFERROR(__xludf.DUMMYFUNCTION("""COMPUTED_VALUE"""),"BNR32") -> BNR32 | D35: =IFERROR(__xludf.DUMMYFUNCTION("""COMPUTED_VALUE"""),"PCVR") -> PCVR | E35: =IFERROR(__xludf.DUMMYFUNCTION("""COMPUTED_VALUE"""),"StarRiver Arts") -> StarRiver Arts | F35: =IFERROR(__xludf.DUMMYFUNCTION("""COMPUTED_VALUE"""),0.002464525462962963) -> 0.0024645255 | G35: =IFERROR(__xludf.DUMMYFUNCTION("""COMPUTED_VALUE"""),"EVOVII/CT9A") -> EVOVII/CT9A | H35: =IFERROR(__xludf.DUMMYFUNCTION("""COMPUTED_VALUE"""),"PC") -> PC | I35: =IFERROR(__xludf.DUMMYFUNCTION("""COMPUTED_VALUE"""),"#N/A") -> #N/A | J35: =IFERROR(__xludf.DUMMYFUNCTION("""COMPUTED_VALUE"""),"#N/A") -> #N/A | K35: =IFERROR(__xludf.DUMMYFUNCTION("""COMPUTED_VALUE"""),"#N/A") -> #N/A | L35: =IFERROR(__xludf.DUMMYFUNCTION("""COMPUTED_VALUE"""),"#N/A") -> #N/A | M35: =IFERROR(__xludf.DUMMYFUNCTION("""COMPUTED_VALUE"""),"#N/A") -> #N/A | N35: =IFERROR(__xludf.DUMMYFUNCTION("""COMPUTED_VALUE"""),"#N/A") -> #N/A | O35: =IFERROR(__xludf.DUMMYFUNCTION("""COMPUTED_VALUE"""),"#N/A") -> #N/A | P35: =IFERROR(__xludf.DUMMYFUNCTION("""COMPUTED_VALUE"""),"#N/A") -> #N/A | Q35: =IFERROR(__xludf.DUMMYFUNCTION("""COMPUTED_VALUE"""),"Kinokono_Tenka") -> Kinokono_Tenka | R35: =IFERROR(__xludf.DUMMYFUNCTION("""COMPUTED_VALUE"""),0.0012289814814814815) -> 0.0012289815 | S35: =IFERROR(__xludf.DUMMYFUNCTION("""COMPUTED_VALUE"""),"LapinTuned") -> LapinTuned | T35: =IFERROR(__xludf.DUMMYFUNCTION("""COMPUTED_VALUE"""),"PCVR") -> PCVR
A36: =IFERROR(__xludf.DUMMYFUNCTION("""COMPUTED_VALUE"""),"~Antidote~") -> ~Antidote~ | B36: =IFERROR(__xludf.DUMMYFUNCTION("""COMPUTED_VALUE"""),0.002233321759259259) -> 0.0022333218 | C36: =IFERROR(__xludf.DUMMYFUNCTION("""COMPUTED_VALUE"""),"EVOVII/CT9A") -> EVOVII/CT9A | D36: =IFERROR(__xludf.DUMMYFUNCTION("""COMPUTED_VALUE"""),"PCVR") -> PCVR | E36: =IFERROR(__xludf.DUMMYFUNCTION("""COMPUTED_VALUE"""),"LinWu_05") -> LinWu_05 | F36: =IFERROR(__xludf.DUMMYFUNCTION("""COMPUTED_VALUE"""),0.0024857407407407406) -> 0.0024857407 | G36: =IFERROR(__xludf.DUMMYFUNCTION("""COMPUTED_VALUE"""),"380SX") -> 380SX | H36: =IFERROR(__xludf.DUMMYFUNCTION("""COMPUTED_VALUE"""),"PC") -> PC | Q36: =IFERROR(__xludf.DUMMYFUNCTION("""COMPUTED_VALUE"""),"_Aqua") -> _Aqua | R36: =IFERROR(__xludf.DUMMYFUNCTION("""COMPUTED_VALUE"""),0.0012419560185185185) -> 0.001241956 | S36: =IFERROR(__xludf.DUMMYFUNCTION("""COMPUTED_VALUE"""),"LapinTuned") -> LapinTuned | T36: =IFERROR(__xludf.DUMMYFUNCTION("""COMPUTED_VALUE"""),"Quest") -> Quest
A37: =IFERROR(__xludf.DUMMYFUNCTION("""COMPUTED_VALUE"""),"Yune") -> Yune | B37: =IFERROR(__xludf.DUMMYFUNCTION("""COMPUTED_VALUE"""),0.002247222222222222) -> 0.0022472222 | C37: =IFERROR(__xludf.DUMMYFUNCTION("""COMPUTED_VALUE"""),"SilEighty") -> SilEighty | D37: =IFERROR(__xludf.DUMMYFUNCTION("""COMPUTED_VALUE"""),"PC") -> PC | E37: =IFERROR(__xludf.DUMMYFUNCTION("""COMPUTED_VALUE"""),"Test Driver") -> Test Driver | F37: =IFERROR(__xludf.DUMMYFUNCTION("""COMPUTED_VALUE"""),0.006944444444444444) -> 0.0069444444 | G37: =IFERROR(__xludf.DUMMYFUNCTION("""COMPUTED_VALUE"""),"BNR32") -> BNR32 | Q37: =IFERROR(__xludf.DUMMYFUNCTION("""COMPUTED_VALUE"""),"Linjeyooo") -> Linjeyooo | R37: =IFERROR(__xludf.DUMMYFUNCTION("""COMPUTED_VALUE"""),0.0012636921296296296) -> 0.0012636921 | S37: =IFERROR(__xludf.DUMMYFUNCTION("""COMPUTED_VALUE"""),"LapinTuned") -> LapinTuned | T37: =IFERROR(__xludf.DUMMYFUNCTION("""COMPUTED_VALUE"""),"PCVR") -> PCVR
A38: =IFERROR(__xludf.DUMMYFUNCTION("""COMPUTED_VALUE"""),"Kinokono_Tenka") -> Kinokono_Tenka | B38: =IFERROR(__xludf.DUMMYFUNCTION("""COMPUTED_VALUE"""),0.0022519675925925923) -> 0.0022519676 | C38: =IFERROR(__xludf.DUMMYFUNCTION("""COMPUTED_VALUE"""),"EG6 (civic)") -> EG6 (civic) | D38: =IFERROR(__xludf.DUMMYFUNCTION("""COMPUTED_VALUE"""),"PCVR") -> PCVR | Q38: =IFERROR(__xludf.DUMMYFUNCTION("""COMPUTED_VALUE"""),"CH-流光-黃") -> CH-流光-黃 | R38: =IFERROR(__xludf.DUMMYFUNCTION("""COMPUTED_VALUE"""),0.0012930787037037036) -> 0.0012930787 | S38: =IFERROR(__xludf.DUMMYFUNCTION("""COMPUTED_VALUE"""),"Macchiato") -> Macchiato | T38: =IFERROR(__xludf.DUMMYFUNCTION("""COMPUTED_VALUE"""),"PCVR") -> PCVR
A39: =IFERROR(__xludf.DUMMYFUNCTION("""COMPUTED_VALUE"""),"StarRiver Arts") -> StarRiver Arts | B39: =IFERROR(__xludf.DUMMYFUNCTION("""COMPUTED_VALUE"""),0.002267546296296296) -> 0.0022675463 | C39: =IFERROR(__xludf.DUMMYFUNCTION("""COMPUTED_VALUE"""),"SilEighty") -> SilEighty | D39: =IFERROR(__xludf.DUMMYFUNCTION("""COMPUTED_VALUE"""),"PC") -> PC | Q39: =IFERROR(__xludf.DUMMYFUNCTION("""COMPUTED_VALUE"""),"起名字好煩人") -> 起名字好煩人 | R39: =IFERROR(__xludf.DUMMYFUNCTION("""COMPUTED_VALUE"""),0.0012930787037037036) -> 0.0012930787 | S39: =IFERROR(__xludf.DUMMYFUNCTION("""COMPUTED_VALUE"""),"EVO3") -> EVO3 | T39: =IFERROR(__xludf.DUMMYFUNCTION("""COMPUTED_VALUE"""),"PCVR") -> PCVR
A40: =IFERROR(__xludf.DUMMYFUNCTION("""COMPUTED_VALUE"""),"ikuhopen") -> ikuhopen | B40: =IFERROR(__xludf.DUMMYFUNCTION("""COMPUTED_VALUE"""),0.0022929050925925925) -> 0.0022929051 | C40: =IFERROR(__xludf.DUMMYFUNCTION("""COMPUTED_VALUE"""),"S14Q") -> S14Q | D40: =IFERROR(__xludf.DUMMYFUNCTION("""COMPUTED_VALUE"""),"PC") -> PC | Q40: =IFERROR(__xludf.DUMMYFUNCTION("""COMPUTED_VALUE"""),"Sakanakokokoko") -> Sakanakokokoko | R40: =IFERROR(__xludf.DUMMYFUNCTION("""COMPUTED_VALUE"""),0.0012951388888888889) -> 0.0012951389 | S40: =IFERROR(__xludf.DUMMYFUNCTION("""COMPUTED_VALUE"""),"CoachKart") -> CoachKart | T40: =IFERROR(__xludf.DUMMYFUNCTION("""COMPUTED_VALUE"""),"PC") -> PC
A41: =IFERROR(__xludf.DUMMYFUNCTION("""COMPUTED_VALUE"""),"Ritcher_Yen") -> Ritcher_Yen | B41: =IFERROR(__xludf.DUMMYFUNCTION("""COMPUTED_VALUE"""),0.0023045833333333334) -> 0.0023045833 | C41: =IFERROR(__xludf.DUMMYFUNCTION("""COMPUTED_VALUE"""),"SilEighty") -> SilEighty | D41: =IFERROR(__xludf.DUMMYFUNCTION("""COMPUTED_VALUE"""),"PC") -> PC | I41: Aiden1408 CVS系統 | Q41: =IFERROR(__xludf.DUMMYFUNCTION("""COMPUTED_VALUE"""),"しんかさん") -> しんかさん | R41: =IFERROR(__xludf.DUMMYFUNCTION("""COMPUTED_VALUE"""),0.0013884027777777777) -> 0.0013884028 | S41: =IFERROR(__xludf.DUMMYFUNCTION("""COMPUTED_VALUE"""),"CoachKart") -> CoachKart | T41: =IFERROR(__xludf.DUMMYFUNCTION("""COMPUTED_VALUE"""),"PCVR") -> PCVR
A42: =IFERROR(__xludf.DUMMYFUNCTION("""COMPUTED_VALUE"""),"Rushia Angel") -> Rushia Angel | B42: =IFERROR(__xludf.DUMMYFUNCTION("""COMPUTED_VALUE"""),0.002318460648148148) -> 0.0023184606 | C42: =IFERROR(__xludf.DUMMYFUNCTION("""COMPUTED_VALUE"""),"EVOVII/CT9A") -> EVOVII/CT9A | D42: =IFERROR(__xludf.DUMMYFUNCTION("""COMPUTED_VALUE"""),"PC") -> PC | I42: Silverstone 銀石F1 | M42: LasVegas 拉斯維加斯F1 | Q42: =IFERROR(__xludf.DUMMYFUNCTION("""COMPUTED_VALUE"""),"你算是惹到棉花了") -> 你算是惹到棉花了 | R42: =IFERROR(__xludf.DUMMYFUNCTION("""COMPUTED_VALUE"""),0.0014482986111111111) -> 0.0014482986 | S42: =IFERROR(__xludf.DUMMYFUNCTION("""COMPUTED_VALUE"""),"Macchiato") -> Macchiato | T42: =IFERROR(__xludf.DUMMYFUNCTION("""COMPUTED_VALUE"""),"PCVR") -> PCVR
...

Sheet 依賽道-車輛紀錄
A1: 作者：Jintei Sacc系統 | I1: 作者：FoxBG CVS系統 | Q1: 作者：StarRiver Arts 跨系統
A2: Akina Downhill秋名/下行 | E2: Akina Uphill秋名/上行 | I2: Nagao Downhill 長尾/下行 | M2: Shomaru Clockwise 正丸/順行 | Q2: 9Turns CVS Downhill 九彎十八拐/下行 | U2: 9Turns CVS Uphill 九彎十八拐/上行
A3: =IFERROR(__xludf.DUMMYFUNCTION("LET( 賽道, ""Akina"", 路線, ""DH"", 系統, ""Sacc"", 原始, FILTER('歷史紀錄'!$E$2:$H1244, '歷史紀錄'!$B2:$B1244=賽道, '歷史紀錄'!$C$2:$C1244=路線, '歷史紀錄'!$I$2:$I1244=系統), 排序後, SORT(原始, 2, TRUE), 車輛, INDEX(排序後,,3), 唯一車輛, UNIQUE(車輛), 結果, MAP(唯一車輛, LAMBDA(p, "&" INDEX(FILTER(排序後, INDEX(排序後,,3)=p),1,0) )), 表頭, {""Player玩家"",""Time時間"",""Car車種"",""Platform平台""}, VSTACK(表頭, 結果) ) "),"Player玩家") -> Player玩家 | B3: =IFERROR(__xludf.DUMMYFUNCTION("""COMPUTED_VALUE"""),"Time時間") -> Time時間 | C3: =IFERROR(__xludf.DUMMYFUNCTION("""COMPUTED_VALUE"""),"Car車種") -> Car車種 | D3: =IFERROR(__xludf.DUMMYFUNCTION("""COMPUTED_VALUE"""),"Platform平台") -> Platform平台 | E3: =IFERROR(__xludf.DUMMYFUNCTION("LET( 賽道, ""Akina"", 路線, ""UH"", 系統, ""Sacc"", 原始, FILTER('歷史紀錄'!$E$2:$H1244, '歷史紀錄'!$B2:$B1244=賽道, '歷史紀錄'!$C$2:$C1244=路線, '歷史紀錄'!$I$2:$I1244=系統), 排序後, SORT(原始, 2, TRUE), 車輛, INDEX(排序後,,3), 唯一車輛, UNIQUE(車輛), 結果, MAP(唯一車輛, LAMBDA(p, "&" INDEX(FILTER(排序後, INDEX(排序後,,3)=p),1,0) )), 表頭, {""Player玩家"",""Time時間"",""Car車種"",""Platform平台""}, VSTACK(表頭, 結果) ) "),"Player玩家") -> Player玩家 | F3: =IFERROR(__xludf.DUMMYFUNCTION("""COMPUTED_VALUE"""),"Time時間") -> Time時間 | G3: =IFERROR(__xludf.DUMMYFUNCTION("""COMPUTED_VALUE"""),"Car車種") -> Car車種 | H3: =IFERROR(__xludf.DUMMYFUNCTION("""COMPUTED_VALUE"""),"Platform平台") -> Platform平台 | I3: =IFERROR(__xludf.DUMMYFUNCTION("LET( 賽道, ""Nagao"", 路線, ""DH"", 系統, ""CVS"", 原始, FILTER('歷史紀錄'!$E$2:$H1244, '歷史紀錄'!$B2:$B1244=賽道, '歷史紀錄'!$C$2:$C1244=路線, '歷史紀錄'!$I$2:$I1244=系統), 排序後, SORT(原始, 2, TRUE), 車輛, INDEX(排序後,,3), 唯一車輛, UNIQUE(車輛), 結果, MAP(唯一車輛, LAMBDA(p, "&" INDEX(FILTER(排序後, INDEX(排序後,,3)=p),1,0) )), 表頭, {""Player玩家"",""Time時間"",""Car車種"",""Platform平台""}, VSTACK(表頭, 結果) ) "),"Player玩家") -> Player玩家 | J3: =IFERROR(__xludf.DUMMYFUNCTION("""COMPUTED_VALUE"""),"Time時間") -> Time時間 | K3: =IFERROR(__xludf.DUMMYFUNCTION("""COMPUTED_VALUE"""),"Car車種") -> Car車種 | L3: =IFERROR(__xludf.DUMMYFUNCTION("""COMPUTED_VALUE"""),"Platform平台") -> Platform平台 | M3: =IFERROR(__xludf.DUMMYFUNCTION("LET( 賽道, ""Shomaru"", 路線, """", 系統, ""CVS"", 原始, FILTER('歷史紀錄'!$E$2:$H1244, '歷史紀錄'!$B2:$B1244=賽道, '歷史紀錄'!$C$2:$C1244=路線, '歷史紀錄'!$I$2:$I1244=系統), 排序後, SORT(原始, 2, TRUE), 車輛, INDEX(排序後,,3), 唯一車輛, UNIQUE(車輛), 結果, MAP(唯一車輛, LAMBDA(p, "&" INDEX(FILTER(排序後, INDEX(排序後,,3)=p),1,0) )), 表頭, {""Player玩家"",""Time時間"",""Car車種"",""Platform平台""}, VSTACK(表頭, 結果) ) "),"Player玩家") -> Player玩家 | N3: =IFERROR(__xludf.DUMMYFUNCTION("""COMPUTED_VALUE"""),"Time時間") -> Time時間 | O3: =IFERROR(__xludf.DUMMYFUNCTION("""COMPUTED_VALUE"""),"Car車種") -> Car車種 | P3: =IFERROR(__xludf.DUMMYFUNCTION("""COMPUTED_VALUE"""),"Platform平台") -> Platform平台 | Q3: =IFERROR(__xludf.DUMMYFUNCTION("LET( 賽道, ""PT:9T"", 路線, ""DH"", 系統, ""CVS"", 原始, FILTER('歷史紀錄'!$E$2:$H1244, '歷史紀錄'!$B$2:$B1244=賽道, '歷史紀錄'!$C$2:$C1244=路線, '歷史紀錄'!$I$2:$I1244=系統), 排序後, SORT(原始, 2, TRUE), 車輛, INDEX(排序後,,3), 唯一車輛, UNIQUE(車輛), 結果, MAP(唯一車輛, LAMBDA(p, "&" INDEX(FILTER(排序後, INDEX(排序後,,3)=p),1,0) )), 表頭, {""Player玩家"",""Time時間"",""Car車種"",""Platform平台""}, VSTACK(表頭, 結果) ) "),"Player玩家") -> Player玩家 | R3: =IFERROR(__xludf.DUMMYFUNCTION("""COMPUTED_VALUE"""),"Time時間") -> Time時間 | S3: =IFERROR(__xludf.DUMMYFUNCTION("""COMPUTED_VALUE"""),"Car車種") -> Car車種 | T3: =IFERROR(__xludf.DUMMYFUNCTION("""COMPUTED_VALUE"""),"Platform平台") -> Platform平台 | U3: Player玩家 | V3: Time時間 | W3: Car車種 | X3: Platform平台
A4: =IFERROR(__xludf.DUMMYFUNCTION("""COMPUTED_VALUE"""),"Lolidia") -> Lolidia | B4: =IFERROR(__xludf.DUMMYFUNCTION("""COMPUTED_VALUE"""),0.0023936574074074073) -> 0.0023936574 | C4: =IFERROR(__xludf.DUMMYFUNCTION("""COMPUTED_VALUE"""),"AE86T-V2") -> AE86T-V2 | D4: =IFERROR(__xludf.DUMMYFUNCTION("""COMPUTED_VALUE"""),"PCVR") -> PCVR | E4: =IFERROR(__xludf.DUMMYFUNCTION("""COMPUTED_VALUE"""),"Lolidia") -> Lolidia | F4: =IFERROR(__xludf.DUMMYFUNCTION("""COMPUTED_VALUE"""),0.002610914351851852) -> 0.0026109144 | G4: =IFERROR(__xludf.DUMMYFUNCTION("""COMPUTED_VALUE"""),"AE86T-V2") -> AE86T-V2 | H4: =IFERROR(__xludf.DUMMYFUNCTION("""COMPUTED_VALUE"""),"PCVR") -> PCVR | I4: =IFERROR(__xludf.DUMMYFUNCTION("""COMPUTED_VALUE"""),"ねぎたま") -> ねぎたま | J4: =IFERROR(__xludf.DUMMYFUNCTION("""COMPUTED_VALUE"""),0.002542025462962963) -> 0.0025420255 | K4: =IFERROR(__xludf.DUMMYFUNCTION("""COMPUTED_VALUE"""),"X7 RR") -> X7 RR | L4: =IFERROR(__xludf.DUMMYFUNCTION("""COMPUTED_VALUE"""),"PCVR") -> PCVR | M4: =IFERROR(__xludf.DUMMYFUNCTION("""COMPUTED_VALUE"""),"#N/A") -> #N/A | N4: =IFERROR(__xludf.DUMMYFUNCTION("""COMPUTED_VALUE"""),"#N/A") -> #N/A | O4: =IFERROR(__xludf.DUMMYFUNCTION("""COMPUTED_VALUE"""),"#N/A") -> #N/A | P4: =IFERROR(__xludf.DUMMYFUNCTION("""COMPUTED_VALUE"""),"#N/A") -> #N/A | Q4: =IFERROR(__xludf.DUMMYFUNCTION("""COMPUTED_VALUE"""),"MotherEVO") -> MotherEVO | R4: =IFERROR(__xludf.DUMMYFUNCTION("""COMPUTED_VALUE"""),0.0038710300925925926) -> 0.0038710301 | S4: =IFERROR(__xludf.DUMMYFUNCTION("""COMPUTED_VALUE"""),"EVOIII/CE9A") -> EVOIII/CE9A | T4: =IFERROR(__xludf.DUMMYFUNCTION("""COMPUTED_VALUE"""),"PCVR") -> PCVR
A5: =IFERROR(__xludf.DUMMYFUNCTION("""COMPUTED_VALUE"""),"Lolidia") -> Lolidia | B5: =IFERROR(__xludf.DUMMYFUNCTION("""COMPUTED_VALUE"""),0.0024071527777777776) -> 0.0024071528 | C5: =IFERROR(__xludf.DUMMYFUNCTION("""COMPUTED_VALUE"""),"GR86/ZN8") -> GR86/ZN8 | D5: =IFERROR(__xludf.DUMMYFUNCTION("""COMPUTED_VALUE"""),"PCVR") -> PCVR | E5: =IFERROR(__xludf.DUMMYFUNCTION("""COMPUTED_VALUE"""),"ZihChin") -> ZihChin | F5: =IFERROR(__xludf.DUMMYFUNCTION("""COMPUTED_VALUE"""),0.0027186689814814816) -> 0.002718669 | G5: =IFERROR(__xludf.DUMMYFUNCTION("""COMPUTED_VALUE"""),"GT86/ZN6") -> GT86/ZN6 | H5: =IFERROR(__xludf.DUMMYFUNCTION("""COMPUTED_VALUE"""),"PC") -> PC | I5: =IFERROR(__xludf.DUMMYFUNCTION("""COMPUTED_VALUE"""),"StarRiver Arts") -> StarRiver Arts | J5: =IFERROR(__xludf.DUMMYFUNCTION("""COMPUTED_VALUE"""),0.0034108796296296296) -> 0.0034108796 | K5: =IFERROR(__xludf.DUMMYFUNCTION("""COMPUTED_VALUE"""),"Karin 96") -> Karin 96 | L5: =IFERROR(__xludf.DUMMYFUNCTION("""COMPUTED_VALUE"""),"PC") -> PC | Q5: =IFERROR(__xludf.DUMMYFUNCTION("""COMPUTED_VALUE"""),"Lolidia") -> Lolidia | R5: =IFERROR(__xludf.DUMMYFUNCTION("""COMPUTED_VALUE"""),0.004538715277777778) -> 0.0045387153 | S5: =IFERROR(__xludf.DUMMYFUNCTION("""COMPUTED_VALUE"""),"SampleCar") -> SampleCar | T5: =IFERROR(__xludf.DUMMYFUNCTION("""COMPUTED_VALUE"""),"PCVR") -> PCVR
A6: =IFERROR(__xludf.DUMMYFUNCTION("""COMPUTED_VALUE"""),"菲娜 希琉絲") -> 菲娜 希琉絲 | B6: =IFERROR(__xludf.DUMMYFUNCTION("""COMPUTED_VALUE"""),0.0025018402777777777) -> 0.0025018403 | C6: =IFERROR(__xludf.DUMMYFUNCTION("""COMPUTED_VALUE"""),"GC8-F (Impreza)") -> GC8-F (Impreza) | D6: =IFERROR(__xludf.DUMMYFUNCTION("""COMPUTED_VALUE"""),"PCVR") -> PCVR | E6: =IFERROR(__xludf.DUMMYFUNCTION("""COMPUTED_VALUE"""),"StarRiver Arts") -> StarRiver Arts | F6: =IFERROR(__xludf.DUMMYFUNCTION("""COMPUTED_VALUE"""),0.0029733796296296296) -> 0.0029733796 | G6: =IFERROR(__xludf.DUMMYFUNCTION("""COMPUTED_VALUE"""),"EVOIV/CN9A") -> EVOIV/CN9A | H6: =IFERROR(__xludf.DUMMYFUNCTION("""COMPUTED_VALUE"""),"PC") -> PC | I6: =IFERROR(__xludf.DUMMYFUNCTION("""COMPUTED_VALUE"""),"Test Driver") -> Test Driver | J6: =IFERROR(__xludf.DUMMYFUNCTION("""COMPUTED_VALUE"""),0.006944444444444444) -> 0.0069444444 | K6: =IFERROR(__xludf.DUMMYFUNCTION("""COMPUTED_VALUE"""),"Comet Custom") -> Comet Custom | Q6: =IFERROR(__xludf.DUMMYFUNCTION("""COMPUTED_VALUE"""),"Yukira雪夜") -> Yukira雪夜 | R6: =IFERROR(__xludf.DUMMYFUNCTION("""COMPUTED_VALUE"""),0.008214108796296296) -> 0.0082141088 | S6: =IFERROR(__xludf.DUMMYFUNCTION("""COMPUTED_VALUE"""),"Bus") -> Bus | T6: =IFERROR(__xludf.DUMMYFUNCTION("""COMPUTED_VALUE"""),"PCVR") -> PCVR
A7: =IFERROR(__xludf.DUMMYFUNCTION("""COMPUTED_VALUE"""),"菲娜 希琉絲") -> 菲娜 希琉絲 | B7: =IFERROR(__xludf.DUMMYFUNCTION("""COMPUTED_VALUE"""),0.0025020254629629633) -> 0.0025020255 | C7: =IFERROR(__xludf.DUMMYFUNCTION("""COMPUTED_VALUE"""),"FD3S (RX7)(TT)") -> FD3S (RX7)(TT) | D7: =IFERROR(__xludf.DUMMYFUNCTION("""COMPUTED_VALUE"""),"PCVR") -> PCVR | E7: =IFERROR(__xludf.DUMMYFUNCTION("""COMPUTED_VALUE"""),"StarRiver Arts") -> StarRiver Arts | F7: =IFERROR(__xludf.DUMMYFUNCTION("""COMPUTED_VALUE"""),0.003138506944444444) -> 0.0031385069 | G7: =IFERROR(__xludf.DUMMYFUNCTION("""COMPUTED_VALUE"""),"S13") -> S13 | H7: =IFERROR(__xludf.DUMMYFUNCTION("""COMPUTED_VALUE"""),"PC") -> PC | I7: =IFERROR(__xludf.DUMMYFUNCTION("""COMPUTED_VALUE"""),"Test Driver") -> Test Driver | J7: =IFERROR(__xludf.DUMMYFUNCTION("""COMPUTED_VALUE"""),0.006944444444444444) -> 0.0069444444 | K7: =IFERROR(__xludf.DUMMYFUNCTION("""COMPUTED_VALUE"""),"N2X") -> N2X
A8: =IFERROR(__xludf.DUMMYFUNCTION("""COMPUTED_VALUE"""),"Kinokono_Tenka") -> Kinokono_Tenka | B8: =IFERROR(__xludf.DUMMYFUNCTION("""COMPUTED_VALUE"""),0.002562048611111111) -> 0.0025620486 | C8: =IFERROR(__xludf.DUMMYFUNCTION("""COMPUTED_VALUE"""),"EG6 (civic)") -> EG6 (civic) | D8: =IFERROR(__xludf.DUMMYFUNCTION("""COMPUTED_VALUE"""),"PCVR") -> PCVR | E8: =IFERROR(__xludf.DUMMYFUNCTION("""COMPUTED_VALUE"""),"StarRiver Arts") -> StarRiver Arts | F8: =IFERROR(__xludf.DUMMYFUNCTION("""COMPUTED_VALUE"""),0.0032594560185185187) -> 0.003259456 | G8: =IFERROR(__xludf.DUMMYFUNCTION("""COMPUTED_VALUE"""),"SW20 (MR2)") -> SW20 (MR2) | H8: =IFERROR(__xludf.DUMMYFUNCTION("""COMPUTED_VALUE"""),"PC") -> PC | I8: =IFERROR(__xludf.DUMMYFUNCTION("""COMPUTED_VALUE"""),"Test Driver") -> Test Driver | J8: =IFERROR(__xludf.DUMMYFUNCTION("""COMPUTED_VALUE"""),0.006944444444444444) -> 0.0069444444 | K8: =IFERROR(__xludf.DUMMYFUNCTION("""COMPUTED_VALUE"""),"Karin Saikou") -> Karin Saikou
A9: =IFERROR(__xludf.DUMMYFUNCTION("""COMPUTED_VALUE"""),"Rushia Angel") -> Rushia Angel | B9: =IFERROR(__xludf.DUMMYFUNCTION("""COMPUTED_VALUE"""),0.0025628472222222224) -> 0.0025628472 | C9: =IFERROR(__xludf.DUMMYFUNCTION("""COMPUTED_VALUE"""),"BNR32") -> BNR32 | D9: =IFERROR(__xludf.DUMMYFUNCTION("""COMPUTED_VALUE"""),"PC") -> PC | E9: =IFERROR(__xludf.DUMMYFUNCTION("""COMPUTED_VALUE"""),"Test Driver") -> Test Driver | F9: =IFERROR(__xludf.DUMMYFUNCTION("""COMPUTED_VALUE"""),0.006944444444444444) -> 0.0069444444 | G9: =IFERROR(__xludf.DUMMYFUNCTION("""COMPUTED_VALUE"""),"180SX") -> 180SX | I9: =IFERROR(__xludf.DUMMYFUNCTION("""COMPUTED_VALUE"""),"Test Driver") -> Test Driver | J9: =IFERROR(__xludf.DUMMYFUNCTION("""COMPUTED_VALUE"""),0.006944444444444444) -> 0.0069444444 | K9: =IFERROR(__xludf.DUMMYFUNCTION("""COMPUTED_VALUE"""),"Highline TT") -> Highline TT | Q9: 9Turns Sacc Downhill 九彎十八拐/下行 | U9: 9Turns Sacc Uphill 九彎十八拐/上行
A10: =IFERROR(__xludf.DUMMYFUNCTION("""COMPUTED_VALUE"""),"StarRiver Arts") -> StarRiver Arts | B10: =IFERROR(__xludf.DUMMYFUNCTION("""COMPUTED_VALUE"""),0.0025968402777777778) -> 0.0025968403 | C10: =IFERROR(__xludf.DUMMYFUNCTION("""COMPUTED_VALUE"""),"EVOIV/CN9A") -> EVOIV/CN9A | D10: =IFERROR(__xludf.DUMMYFUNCTION("""COMPUTED_VALUE"""),"PC") -> PC | E10: =IFERROR(__xludf.DUMMYFUNCTION("""COMPUTED_VALUE"""),"Test Driver") -> Test Driver | F10: =IFERROR(__xludf.DUMMYFUNCTION("""COMPUTED_VALUE"""),0.006944444444444444) -> 0.0069444444 | G10: =IFERROR(__xludf.DUMMYFUNCTION("""COMPUTED_VALUE"""),"S15") -> S15 | I10: =IFERROR(__xludf.DUMMYFUNCTION("""COMPUTED_VALUE"""),"Test Driver") -> Test Driver | J10: =IFERROR(__xludf.DUMMYFUNCTION("""COMPUTED_VALUE"""),0.006944444444444444) -> 0.0069444444 | K10: =IFERROR(__xludf.DUMMYFUNCTION("""COMPUTED_VALUE"""),"285xs") -> 285xs | Q10: Player玩家 | R10: Time時間 | S10: Car車種 | T10: Platform平台 | U10: Player玩家 | V10: Time時間 | W10: Car車種 | X10: Platform平台
A11: =IFERROR(__xludf.DUMMYFUNCTION("""COMPUTED_VALUE"""),"アビドサスヒカリ") -> アビドサスヒカリ | B11: =IFERROR(__xludf.DUMMYFUNCTION("""COMPUTED_VALUE"""),0.0025991550925925926) -> 0.0025991551 | C11: =IFERROR(__xludf.DUMMYFUNCTION("""COMPUTED_VALUE"""),"S30Z(Nissan Fairlady Z/Devil Z)") -> S30Z(Nissan Fairlady Z/Devil Z) | D11: =IFERROR(__xludf.DUMMYFUNCTION("""COMPUTED_VALUE"""),"PC") -> PC | E11: =IFERROR(__xludf.DUMMYFUNCTION("""COMPUTED_VALUE"""),"Test Driver") -> Test Driver | F11: =IFERROR(__xludf.DUMMYFUNCTION("""COMPUTED_VALUE"""),0.006944444444444444) -> 0.0069444444 | G11: =IFERROR(__xludf.DUMMYFUNCTION("""COMPUTED_VALUE"""),"FD3S (RX7)(ST)") -> FD3S (RX7)(ST) | I11: =IFERROR(__xludf.DUMMYFUNCTION("""COMPUTED_VALUE"""),"Test Driver") -> Test Driver | J11: =IFERROR(__xludf.DUMMYFUNCTION("""COMPUTED_VALUE"""),0.006944444444444444) -> 0.0069444444 | K11: =IFERROR(__xludf.DUMMYFUNCTION("""COMPUTED_VALUE"""),"GT106") -> GT106
A12: =IFERROR(__xludf.DUMMYFUNCTION("""COMPUTED_VALUE"""),"StarRiver Arts") -> StarRiver Arts | B12: =IFERROR(__xludf.DUMMYFUNCTION("""COMPUTED_VALUE"""),0.0026064814814814818) -> 0.0026064815 | C12: =IFERROR(__xludf.DUMMYFUNCTION("""COMPUTED_VALUE"""),"S15") -> S15 | D12: =IFERROR(__xludf.DUMMYFUNCTION("""COMPUTED_VALUE"""),"PC") -> PC | E12: =IFERROR(__xludf.DUMMYFUNCTION("""COMPUTED_VALUE"""),"Test Driver") -> Test Driver | F12: =IFERROR(__xludf.DUMMYFUNCTION("""COMPUTED_VALUE"""),0.006944444444444444) -> 0.0069444444 | G12: =IFERROR(__xludf.DUMMYFUNCTION("""COMPUTED_VALUE"""),"FC3S (RX7)") -> FC3S (RX7) | I12: =IFERROR(__xludf.DUMMYFUNCTION("""COMPUTED_VALUE"""),"Test Driver") -> Test Driver | J12: =IFERROR(__xludf.DUMMYFUNCTION("""COMPUTED_VALUE"""),0.006944444444444444) -> 0.0069444444 | K12: =IFERROR(__xludf.DUMMYFUNCTION("""COMPUTED_VALUE"""),"Highline T2 XL") -> Highline T2 XL
A13: =IFERROR(__xludf.DUMMYFUNCTION("""COMPUTED_VALUE"""),"アビドサスヒカリ") -> アビドサスヒカリ | B13: =IFERROR(__xludf.DUMMYFUNCTION("""COMPUTED_VALUE"""),0.0027160995370370373) -> 0.0027160995 | C13: =IFERROR(__xludf.DUMMYFUNCTION("""COMPUTED_VALUE"""),"GT86/ZN6") -> GT86/ZN6 | D13: =IFERROR(__xludf.DUMMYFUNCTION("""COMPUTED_VALUE"""),"PC") -> PC | E13: =IFERROR(__xludf.DUMMYFUNCTION("""COMPUTED_VALUE"""),"Test Driver") -> Test Driver | F13: =IFERROR(__xludf.DUMMYFUNCTION("""COMPUTED_VALUE"""),0.006944444444444444) -> 0.0069444444 | G13: =IFERROR(__xludf.DUMMYFUNCTION("""COMPUTED_VALUE"""),"S14") -> S14 | I13: =IFERROR(__xludf.DUMMYFUNCTION("""COMPUTED_VALUE"""),"Test Driver") -> Test Driver | J13: =IFERROR(__xludf.DUMMYFUNCTION("""COMPUTED_VALUE"""),0.006944444444444444) -> 0.0069444444 | K13: =IFERROR(__xludf.DUMMYFUNCTION("""COMPUTED_VALUE"""),"280xs") -> 280xs
A14: =IFERROR(__xludf.DUMMYFUNCTION("""COMPUTED_VALUE"""),"StarRiver Arts") -> StarRiver Arts | B14: =IFERROR(__xludf.DUMMYFUNCTION("""COMPUTED_VALUE"""),0.0027644675925925927) -> 0.0027644676 | C14: =IFERROR(__xludf.DUMMYFUNCTION("""COMPUTED_VALUE"""),"AE86L-V2") -> AE86L-V2 | D14: =IFERROR(__xludf.DUMMYFUNCTION("""COMPUTED_VALUE"""),"PC") -> PC | E14: =IFERROR(__xludf.DUMMYFUNCTION("""COMPUTED_VALUE"""),"Test Driver") -> Test Driver | F14: =IFERROR(__xludf.DUMMYFUNCTION("""COMPUTED_VALUE"""),0.006944444444444444) -> 0.0069444444 | G14: =IFERROR(__xludf.DUMMYFUNCTION("""COMPUTED_VALUE"""),"Blackbird") -> Blackbird | I14: =IFERROR(__xludf.DUMMYFUNCTION("""COMPUTED_VALUE"""),"Test Driver") -> Test Driver | J14: =IFERROR(__xludf.DUMMYFUNCTION("""COMPUTED_VALUE"""),0.006944444444444444) -> 0.0069444444 | K14: =IFERROR(__xludf.DUMMYFUNCTION("""COMPUTED_VALUE"""),"Highline T2 ") -> Highline T2 | Q14: StarSight Touge Downhill觀星山/下行 | U14: StarSight Touge Uphill觀星山/上行
A15: =IFERROR(__xludf.DUMMYFUNCTION("""COMPUTED_VALUE"""),"StarRiver Arts") -> StarRiver Arts | B15: =IFERROR(__xludf.DUMMYFUNCTION("""COMPUTED_VALUE"""),0.0028387384259259255) -> 0.0028387384 | C15: =IFERROR(__xludf.DUMMYFUNCTION("""COMPUTED_VALUE"""),"S13") -> S13 | D15: =IFERROR(__xludf.DUMMYFUNCTION("""COMPUTED_VALUE"""),"PC") -> PC | E15: =IFERROR(__xludf.DUMMYFUNCTION("""COMPUTED_VALUE"""),"Test Driver") -> Test Driver | F15: =IFERROR(__xludf.DUMMYFUNCTION("""COMPUTED_VALUE"""),0.006944444444444444) -> 0.0069444444 | G15: =IFERROR(__xludf.DUMMYFUNCTION("""COMPUTED_VALUE"""),"DB42 (GR Supra)") -> DB42 (GR Supra) | I15: =IFERROR(__xludf.DUMMYFUNCTION("""COMPUTED_VALUE"""),"Test Driver") -> Test Driver | J15: =IFERROR(__xludf.DUMMYFUNCTION("""COMPUTED_VALUE"""),0.006944444444444444) -> 0.0069444444 | K15: =IFERROR(__xludf.DUMMYFUNCTION("""COMPUTED_VALUE"""),"Karin Intruder") -> Karin Intruder | Q15: =IFERROR(__xludf.DUMMYFUNCTION("LET( 賽道, ""StarSight"", 路線, ""DH"", 系統, ""CVS"", 原始, FILTER('歷史紀錄'!$E$2:$H1244, '歷史紀錄'!$B$2:$B1244=賽道, '歷史紀錄'!$C$2:$C1244=路線, '歷史紀錄'!$I$2:$I1244=系統), 排序後, SORT(原始, 2, TRUE), 車輛, INDEX(排序後,,3), 唯一車輛, UNIQUE(車輛), 結果, MAP(唯一車輛, LAMBDA(p, "&" INDEX(FILTER(排序後, INDEX(排序後,,3)=p),1,0) )), 表頭, {""Player玩家"",""Time時間"",""Car車種"",""Platform平台""}, VSTACK(表頭, 結果) ) "),"Player玩家") -> Player玩家 | R15: =IFERROR(__xludf.DUMMYFUNCTION("""COMPUTED_VALUE"""),"Time時間") -> Time時間 | S15: =IFERROR(__xludf.DUMMYFUNCTION("""COMPUTED_VALUE"""),"Car車種") -> Car車種 | T15: =IFERROR(__xludf.DUMMYFUNCTION("""COMPUTED_VALUE"""),"Platform平台") -> Platform平台 | U15: =IFERROR(__xludf.DUMMYFUNCTION("LET( 賽道, ""StarSight"", 路線, ""UH"", 系統, ""CVS"", 原始, FILTER('歷史紀錄'!$E$2:$H1244, '歷史紀錄'!$B$2:$B1244=賽道, '歷史紀錄'!$C$2:$C1244=路線, '歷史紀錄'!$I$2:$I1244=系統), 排序後, SORT(原始, 2, TRUE), 車輛, INDEX(排序後,,3), 唯一車輛, UNIQUE(車輛), 結果, MAP(唯一車輛, LAMBDA(p, "&" INDEX(FILTER(排序後, INDEX(排序後,,3)=p),1,0) )), 表頭, {""Player玩家"",""Time時間"",""Car車種"",""Platform平台""}, VSTACK(表頭, 結果) ) "),"Player玩家") -> Player玩家 | V15: =IFERROR(__xludf.DUMMYFUNCTION("""COMPUTED_VALUE"""),"Time時間") -> Time時間 | W15: =IFERROR(__xludf.DUMMYFUNCTION("""COMPUTED_VALUE"""),"Car車種") -> Car車種 | X15: =IFERROR(__xludf.DUMMYFUNCTION("""COMPUTED_VALUE"""),"Platform平台") -> Platform平台
A16: =IFERROR(__xludf.DUMMYFUNCTION("""COMPUTED_VALUE"""),"StarRiver Arts") -> StarRiver Arts | B16: =IFERROR(__xludf.DUMMYFUNCTION("""COMPUTED_VALUE"""),0.0028537847222222224) -> 0.0028537847 | C16: =IFERROR(__xludf.DUMMYFUNCTION("""COMPUTED_VALUE"""),"Hurricant(LB724)") -> Hurricant(LB724) | D16: =IFERROR(__xludf.DUMMYFUNCTION("""COMPUTED_VALUE"""),"PC") -> PC | E16: =IFERROR(__xludf.DUMMYFUNCTION("""COMPUTED_VALUE"""),"Test Driver") -> Test Driver | F16: =IFERROR(__xludf.DUMMYFUNCTION("""COMPUTED_VALUE"""),0.006944444444444444) -> 0.0069444444 | G16: =IFERROR(__xludf.DUMMYFUNCTION("""COMPUTED_VALUE"""),"AE86L-V2") -> AE86L-V2 | I16: =IFERROR(__xludf.DUMMYFUNCTION("""COMPUTED_VALUE"""),"Test Driver") -> Test Driver | J16: =IFERROR(__xludf.DUMMYFUNCTION("""COMPUTED_VALUE"""),0.006944444444444444) -> 0.0069444444 | K16: =IFERROR(__xludf.DUMMYFUNCTION("""COMPUTED_VALUE"""),"284xs") -> 284xs | Q16: =IFERROR(__xludf.DUMMYFUNCTION("""COMPUTED_VALUE"""),"Lolidia") -> Lolidia | R16: =IFERROR(__xludf.DUMMYFUNCTION("""COMPUTED_VALUE"""),0.0010182638888888889) -> 0.0010182639 | S16: =IFERROR(__xludf.DUMMYFUNCTION("""COMPUTED_VALUE"""),"EVO3") -> EVO3 | T16: =IFERROR(__xludf.DUMMYFUNCTION("""COMPUTED_VALUE"""),"PCVR") -> PCVR | U16: =IFERROR(__xludf.DUMMYFUNCTION("""COMPUTED_VALUE"""),"#N/A") -> #N/A | V16: =IFERROR(__xludf.DUMMYFUNCTION("""COMPUTED_VALUE"""),"#N/A") -> #N/A | W16: =IFERROR(__xludf.DUMMYFUNCTION("""COMPUTED_VALUE"""),"#N/A") -> #N/A | X16: =IFERROR(__xludf.DUMMYFUNCTION("""COMPUTED_VALUE"""),"#N/A") -> #N/A
A17: =IFERROR(__xludf.DUMMYFUNCTION("""COMPUTED_VALUE"""),"StarRiver Arts") -> StarRiver Arts | B17: =IFERROR(__xludf.DUMMYFUNCTION("""COMPUTED_VALUE"""),0.0032253124999999994) -> 0.0032253125 | C17: =IFERROR(__xludf.DUMMYFUNCTION("""COMPUTED_VALUE"""),"AE86T") -> AE86T | D17: =IFERROR(__xludf.DUMMYFUNCTION("""COMPUTED_VALUE"""),"PC") -> PC | E17: =IFERROR(__xludf.DUMMYFUNCTION("""COMPUTED_VALUE"""),"Test Driver") -> Test Driver | F17: =IFERROR(__xludf.DUMMYFUNCTION("""COMPUTED_VALUE"""),0.006944444444444444) -> 0.0069444444 | G17: =IFERROR(__xludf.DUMMYFUNCTION("""COMPUTED_VALUE"""),"Hurricant(LB724)") -> Hurricant(LB724) | Q17: =IFERROR(__xludf.DUMMYFUNCTION("""COMPUTED_VALUE"""),"Light_Spirit") -> Light_Spirit | R17: =IFERROR(__xludf.DUMMYFUNCTION("""COMPUTED_VALUE"""),0.0010786226851851853) -> 0.0010786227 | S17: =IFERROR(__xludf.DUMMYFUNCTION("""COMPUTED_VALUE"""),"Macchiato") -> Macchiato | T17: =IFERROR(__xludf.DUMMYFUNCTION("""COMPUTED_VALUE"""),"PCVR") -> PCVR
